Workbook

Sheet Regras
B1: BOLÃO COPA DO MUNDO 2026
B2: REGULAMENTO OFICIAL
B3: COMO FUNCIONA | C3: PRAZO
B4: Envio único antes da Copa. O participante deverá preencher todos os palpites de uma só vez: fase de grupos e bônus. Após o envio, não serão aceitas alterações. | C4: 18/05/2026 até 10/06/2026
B5: Preencha seu nome na célula A5 da aba “Apostas - Grupos” e renomeie este arquivo substituindo “{Seu Nome}” pelo mesmo nome informado na planilha.. Exemplo -> Bolao_Copa2026_Pedro Brandão.xlsx
B6: Para confirmar sua presença envie esta planilha preenchida para pedroh.brandao@hotmail.com com o assunto "Bolão Copa do Mundo - {Seu Nome}" e realize o PIX de R$ 100,00 até o prazo limite. Chave PIX: 21994980610 (Claudio Coutada)
B8: APOSTAS - GRUPOS (max 360 pts)
B9: Placar Exato (ex: 2x1 apostado, 2x1 real) | C9: 5 pontos
B10: Saldo Correto (2x0 apostado, 3x1 real / 1x1 apostado, 0x0 real) | C10: 3 pontos
B11: Apenas Vencedor Correto (1x0 apostado, 3x0 real) | C11: 2 pontos
B12: Resultado Errado | C12: 0 pontos
B14: APOSTAS - BONUS (max 20 pts)
B15: Artilheiro da fase de grupos | C15: 20 pontos
B17: CRITÉRIOS DE DESEMPATE
B18: 1o) Maior numero de acertos de 5 pts na fase de grupos.
B19: 2o) Maior numero de acertos de 3 pts na fase de grupos.
B20: 3o) Sorteio.
B22: PREMIAÇÃO
B23: PRIMEIRO LUGAR = 70% DO PRÊMIO
B24: SEGUNDO LUGAR = 20% DO PRÊMIO
B25: TERCEIRO LUGAR = 10% DO PRÊMIO

Sheet Apostas - Grupos
A1: BOLAO 2026 - APOSTAS: FASE DE GRUPOS
A2: Preencha as celulas AMARELAS com os placares previstos. Role para a direita para ver todos os 72 jogos.
A3: Participante | B3: G001 (A) | D3: G002 (A) | F3: G003 (A) | H3: G004 (A) | J3: G005 (A) | L3: G006 (A) | N3: G007 (B) | P3: G008 (B) | R3: G009 (B) | T3: G010 (B) | V3: G011 (B) | X3: G012 (B) | Z3: G013 (C) | AB3: G014 (C) | AD3: G015 (C) | AF3: G016 (C) | AH3: G017 (C) | AJ3: G018 (C) | AL3: G019 (D) | AN3: G020 (D) | AP3: G021 (D) | AR3: G022 (D) | AT3: G023 (D) | AV3: G024 (D) | AX3: G025 (E) | AZ3: G026 (E) | BB3: G027 (E) | BD3: G028 (E) | BF3: G029 (E) | BH3: G030 (E) | BJ3: G031 (F) | BL3: G032 (F) | BN3: G033 (F) | BP3: G034 (F) | BR3: G035 (F) | BT3: G036 (F) | BV3: G037 (G) | BX3: G038 (G) | BZ3: G039 (G) | CB3: G040 (G) | CD3: G041 (G) | CF3: G042 (G) | CH3: G043 (H) | CJ3: G044 (H) | CL3: G045 (H) | CN3: G046 (H) | CP3: G047 (H) | CR3: G048 (H) | CT3: G049 (I) | CV3: G050 (I) | CX3: G051 (I) | CZ3: G052 (I) | DB3: G053 (I) | DD3: G054 (I) | DF3: G055 (J) | DH3: G056 (J) | DJ3: G057 (J) | DL3: G058 (J) | DN3: G059 (J) | DP3: G060 (J) | DR3: G061 (K) | DT3: G062 (K) | DV3: G063 (K) | DX3: G064 (K) | DZ3: G065 (K) | EB3: G066 (K) | ED3: G067 (L) | EF3: G068 (L) | EH3: G069 (L) | EJ3: G070 (L) | EL3: G071 (L) | EN3: G072 (L)
A4: Nome | B4: Mexico | C4: Africa do Sul | D4: Coreia do Sul | E4: Tchequia | F4: Tchequia | G4: Africa do Sul | H4: Mexico | I4: Coreia do Sul | J4: Tchequia | K4: Mexico | L4: Africa do Sul | M4: Coreia do Sul | N4: Canada | O4: Bosnia e Herzegovina | P4: Qatar | Q4: Suica | R4: Suica | S4: Bosnia e Herzegovina | T4: Canada | U4: Qatar | V4: Suica | W4: Canada | X4: Bosnia e Herzegovina | Y4: Qatar | Z4: Brasil | AA4: Marrocos | AB4: Haiti | AC4: Escocia | AD4: Escocia | AE4: Marrocos | AF4: Brasil | AG4: Haiti | AH4: Escocia | AI4: Brasil | AJ4: Marrocos | AK4: Haiti | AL4: Estados Unidos | AM4: Paraguai | AN4: Australia | AO4: Turquia | AP4: Estados Unidos | AQ4: Australia | AR4: Turquia | AS4: Paraguai | AT4: Turquia | AU4: Estados Unidos | AV4: Paraguai | AW4: Australia | AX4: Alemanha | AY4: Curacao | AZ4: Costa do Marfim | BA4: Equador | BB4: Alemanha | BC4: Costa do Marfim | BD4: Equador | BE4: Curacao | BF4: Equador | BG4: Alemanha | BH4: Curacao | BI4: Costa do Marfim | BJ4: Holanda | BK4: Japao | BL4: Suecia | BM4: Tunisia | BN4: Holanda | BO4: Suecia | BP4: Tunisia | BQ4: Japao | BR4: Japao | BS4: Suecia | BT4: Tunisia | BU4: Holanda | BV4: Belgica | BW4: Egito | BX4: Ira | BY4: Nova Zelandia | BZ4: Belgica | CA4: Ira | CB4: Nova Zelandia | CC4: Egito | CD4: Egito | CE4: Ira | CF4: Nova Zelandia | CG4: Belgica | CH4: Espanha | CI4: Cabo Verde | CJ4: Arabia Saudita | CK4: Uruguai | CL4: Espanha | CM4: Arabia Saudita | CN4: Uruguai | CO4: Cabo Verde | CP4: Cabo Verde | CQ4: Arabia Saudita | CR4: Uruguai | CS4: Espanha | CT4: Franca | CU4: Senegal | CV4: Iraque | CW4: Noruega | CX4: Franca | CY4: Iraque | CZ4: Noruega | DA4: Senegal | DB4: Noruega | DC4: Franca | DD4: Senegal | DE4: Iraque | DF4: Argentina | DG4: Argelia | DH4: Austria | DI4: Jordania | DJ4: Argentina | DK4: Austria | DL4: Jordania | DM4: Argelia | DN4: Argelia | DO4: Austria | DP4: Jordania | DQ4: Argentina | DR4: Portugal | DS4: RD Congo | DT4: Uzbequistao | DU4: Colombia | DV4: Portugal | DW4: Uzbequistao | DX4: Colombia | DY4: RD Congo | DZ4: Colombia | EA4: Portugal | EB4: RD Congo | EC4: Uzbequistao | ED4: Inglaterra | EE4: Croacia | EF4: Gana | EG4: Panama | EH4: Inglaterra | EI4: Gana | EJ4: Panama | EK4: Croacia | EL4: Panama | EM4: Inglaterra | EN4: Croacia | EO4: Gana
A5: Wilson ( Oasis ) | B5: 2 | C5: 0 | D5: 1 | E5: 1 | F5: 3 | G5: 1 | H5: 2 | I5: 1 | J5: 1 | K5: 1 | L5: 1 | M5: 2 | N5: 1 | O5: 1 | P5: 0 | Q5: 2 | R5: 3 | S5: 1 | T5: 2 | U5: 0 | V5: 1 | W5: 1 | X5: 2 | Y5: 2 | Z5: 2 | AA5: 1 | AB5: 0 | AC5: 3 | AD5: 0 | AE5: 2 | AF5: 4 | AG5: 0 | AH5: 0 | AI5: 2 | AJ5: 3 | AK5: 0 | AL5: 1 | AM5: 1 | AN5: 1 | AO5: 3 | AP5: 2 | AQ5: 0 | AR5: 0 | AS5: 0 | AT5: 1 | AU5: 1 | AV5: 3 | AW5: 1 | AX5: 3 | AY5: 0 | AZ5: 1 | BA5: 1 | BB5: 2 | BC5: 1 | BD5: 3 | BE5: 0 | BF5: 1 | BG5: 3 | BH5: 0 | BI5: 2 | BJ5: 1 | BK5: 1 | BL5: 2 | BM5: 1 | BN5: 2 | BO5: 2 | BP5: 0 | BQ5: 3 | BR5: 2 | BS5: 0 | BT5: 0 | BU5: 2 | BV5: 3 | BW5: 1 | BX5: 0 | BY5: 1 | BZ5: 3 | CA5: 0 | CB5: 1 | CC5: 1 | CD5: 2 | CE5: 0 | CF5: 1 | CG5: 3 | CH5: 4 | CI5: 0 | CJ5: 0 | CK5: 2 | CL5: 2 | CM5: 0 | CN5: 3 | CO5: 1 | CP5: 1 | CQ5: 1 | CR5: 2 | CS5: 3 | CT5: 2 | CU5: 0 | CV5: 0 | CW5: 2 | CX5: 3 | CY5: 0 | CZ5: 2 | DA5: 1 | DB5: 1 | DC5: 2 | DD5: 3 | DE5: 1 | DF5: 2 | DG5: 0 | DH5: 1 | DI5: 0 | DJ5: 2 | DK5: 0 | DL5: 1 | DM5: 3 | DN5: 1 | DO5: 1 | DP5: 0 | DQ5: 3 | DR5: 3 | DS5: 0 | DT5: 0 | DU5: 2 | DV5: 3 | DW5: 0 | DX5: 2 | DY5: 0 | DZ5: 2 | EA5: 2 | EB5: 0 | EC5: 0 | ED5: 2 | EE5: 1 | EF5: 3 | EG5: 1 | EH5: 3 | EI5: 1 | EJ5: 0 | EK5: 2 | EL5: 0 | EM5: 3 | EN5: 2 | EO5: 2
A7: CLASSIFICAÇÃO POR GRUPO (atualiza automaticamente conforme você preenche os placares)
A8: Grupo A | Q8: Grupo B | AG8: Grupo C
A9: # | B9: Seleção | H9: P | I9: J | J9: V | K9: E | L9: D | M9: GP | N9: GC | O9: SG | P9: % | Q9: # | R9: Seleção | X9: P | Y9: J | Z9: V | AA9: E | AB9: D | AC9: GP | AD9: GC | AE9: SG | AF9: % | AG9: # | AH9: Seleção | AN9: P | AO9: J | AP9: V | AQ9: E | AR9: D | AS9: GP | AT9: GC | AU9: SG | AV9: %
A10: 1 | B10: =IFERROR(INDEX(Calc!$B$3:$B$6,MATCH(1,Calc!$J$3:$J$6,0)),"?") -> Mexico | H10: =IFERROR(INDEX(Calc!$H$3:$H$6,MATCH(1,Calc!$J$3:$J$6,0)),0) -> 7 | I10: =IFERROR(INDEX(Calc!$K$3:$K$6,MATCH(1,Calc!$J$3:$J$6,0)),0) -> 3 | J10: =IFERROR(INDEX(Calc!$C$3:$C$6,MATCH(1,Calc!$J$3:$J$6,0)),0) -> 2 | K10: =IFERROR(INDEX(Calc!$D$3:$D$6,MATCH(1,Calc!$J$3:$J$6,0)),0) -> 1 | L10: =IFERROR(INDEX(Calc!$L$3:$L$6,MATCH(1,Calc!$J$3:$J$6,0)),0) -> 0 | M10: =IFERROR(INDEX(Calc!$E$3:$E$6,MATCH(1,Calc!$J$3:$J$6,0)),0) -> 5 | N10: =IFERROR(INDEX(Calc!$F$3:$F$6,MATCH(1,Calc!$J$3:$J$6,0)),0) -> 2 | O10: =IFERROR(INDEX(Calc!$G$3:$G$6,MATCH(1,Calc!$J$3:$J$6,0)),0) -> 3 | P10: =IFERROR(ROUND(INDEX(Calc!$H$3:$H$6,MATCH(1,Calc!$J$3:$J$6,0))/(INDEX(Calc!$K$3:$K$6,MATCH(1,Calc!$J$3:$J$6,0))*3)*100,0),0) -> 78 | Q10: 1 | R10: =IFERROR(INDEX(Calc!$B$7:$B$10,MATCH(1,Calc!$J$7:$J$10,0)),"?") -> Suica | X10: =IFERROR(INDEX(Calc!$H$7:$H$10,MATCH(1,Calc!$J$7:$J$10,0)),0) -> 7 | Y10: =IFERROR(INDEX(Calc!$K$7:$K$10,MATCH(1,Calc!$J$7:$J$10,0)),0) -> 3 | Z10: =IFERROR(INDEX(Calc!$C$7:$C$10,MATCH(1,Calc!$J$7:$J$10,0)),0) -> 2 | AA10: =IFERROR(INDEX(Calc!$D$7:$D$10,MATCH(1,Calc!$J$7:$J$10,0)),0) -> 1 | AB10: =IFERROR(INDEX(Calc!$L$7:$L$10,MATCH(1,Calc!$J$7:$J$10,0)),0) -> 0 | AC10: =IFERROR(INDEX(Calc!$E$7:$E$10,MATCH(1,Calc!$J$7:$J$10,0)),0) -> 6 | AD10: =IFERROR(INDEX(Calc!$F$7:$F$10,MATCH(1,Calc!$J$7:$J$10,0)),0) -> 2 | AE10: =IFERROR(INDEX(Calc!$G$7:$G$10,MATCH(1,Calc!$J$7:$J$10,0)),0) -> 4 | AF10: =IFERROR(ROUND(INDEX(Calc!$H$7:$H$10,MATCH(1,Calc!$J$7:$J$10,0))/(INDEX(Calc!$K$7:$K$10,MATCH(1,Calc!$J$7:$J$10,0))*3)*100,0),0) -> 78 | AG10: 1 | AH10: =IFERROR(INDEX(Calc!$B$11:$B$14,MATCH(1,Calc!$J$11:$J$14,0)),"?") -> Brasil | AN10: =IFERROR(INDEX(Calc!$H$11:$H$14,MATCH(1,Calc!$J$11:$J$14,0)),0) -> 9 | AO10: =IFERROR(INDEX(Calc!$K$11:$K$14,MATCH(1,Calc!$J$11:$J$14,0)),0) -> 3 | AP10: =IFERROR(INDEX(Calc!$C$11:$C$14,MATCH(1,Calc!$J$11:$J$14,0)),0) -> 3 | AQ10: =IFERROR(INDEX(Calc!$D$11:$D$14,MATCH(1,Calc!$J$11:$J$14,0)),0) -> 0 | AR10: =IFERROR(INDEX(Calc!$L$11:$L$14,MATCH(1,Calc!$J$11:$J$14,0)),0) -> 0 | AS10: =IFERROR(INDEX(Calc!$E$11:$E$14,MATCH(1,Calc!$J$11:$J$14,0)),0) -> 8 | AT10: =IFERROR(INDEX(Calc!$F$11:$F$14,MATCH(1,Calc!$J$11:$J$14,0)),0) -> 1 | AU10: =IFERROR(INDEX(Calc!$G$11:$G$14,MATCH(1,Calc!$J$11:$J$14,0)),0) -> 7 | AV10: =IFERROR(ROUND(INDEX(Calc!$H$11:$H$14,MATCH(1,Calc!$J$11:$J$14,0))/(INDEX(Calc!$K$11:$K$14,MATCH(1,Calc!$J$11:$J$14,0))*3)*100,0),0) -> 100
A11: 2 | B11: =IFERROR(INDEX(Calc!$B$3:$B$6,MATCH(2,Calc!$J$3:$J$6,0)),"?") -> Tchequia | H11: =IFERROR(INDEX(Calc!$H$3:$H$6,MATCH(2,Calc!$J$3:$J$6,0)),0) -> 5 | I11: =IFERROR(INDEX(Calc!$K$3:$K$6,MATCH(2,Calc!$J$3:$J$6,0)),0) -> 3 | J11: =IFERROR(INDEX(Calc!$C$3:$C$6,MATCH(2,Calc!$J$3:$J$6,0)),0) -> 1 | K11: =IFERROR(INDEX(Calc!$D$3:$D$6,MATCH(2,Calc!$J$3:$J$6,0)),0) -> 2 | L11: =IFERROR(INDEX(Calc!$L$3:$L$6,MATCH(2,Calc!$J$3:$J$6,0)),0) -> 0 | M11: =IFERROR(INDEX(Calc!$E$3:$E$6,MATCH(2,Calc!$J$3:$J$6,0)),0) -> 5 | N11: =IFERROR(INDEX(Calc!$F$3:$F$6,MATCH(2,Calc!$J$3:$J$6,0)),0) -> 3 | O11: =IFERROR(INDEX(Calc!$G$3:$G$6,MATCH(2,Calc!$J$3:$J$6,0)),0) -> 2 | P11: =IFERROR(ROUND(INDEX(Calc!$H$3:$H$6,MATCH(2,Calc!$J$3:$J$6,0))/(INDEX(Calc!$K$3:$K$6,MATCH(2,Calc!$J$3:$J$6,0))*3)*100,0),0) -> 56 | Q11: 2 | R11: =IFERROR(INDEX(Calc!$B$7:$B$10,MATCH(2,Calc!$J$7:$J$10,0)),"?") -> Canada | X11: =IFERROR(INDEX(Calc!$H$7:$H$10,MATCH(2,Calc!$J$7:$J$10,0)),0) -> 5 | Y11: =IFERROR(INDEX(Calc!$K$7:$K$10,MATCH(2,Calc!$J$7:$J$10,0)),0) -> 3 | Z11: =IFERROR(INDEX(Calc!$C$7:$C$10,MATCH(2,Calc!$J$7:$J$10,0)),0) -> 1 | AA11: =IFERROR(INDEX(Calc!$D$7:$D$10,MATCH(2,Calc!$J$7:$J$10,0)),0) -> 2 | AB11: =IFERROR(INDEX(Calc!$L$7:$L$10,MATCH(2,Calc!$J$7:$J$10,0)),0) -> 0 | AC11: =IFERROR(INDEX(Calc!$E$7:$E$10,MATCH(2,Calc!$J$7:$J$10,0)),0) -> 4 | AD11: =IFERROR(INDEX(Calc!$F$7:$F$10,MATCH(2,Calc!$J$7:$J$10,0)),0) -> 2 | AE11: =IFERROR(INDEX(Calc!$G$7:$G$10,MATCH(2,Calc!$J$7:$J$10,0)),0) -> 2 | AF11: =IFERROR(ROUND(INDEX(Calc!$H$7:$H$10,MATCH(2,Calc!$J$7:$J$10,0))/(INDEX(Calc!$K$7:$K$10,MATCH(2,Calc!$J$7:$J$10,0))*3)*100,0),0) -> 56 | AG11: 2 | AH11: =IFERROR(INDEX(Calc!$B$11:$B$14,MATCH(2,Calc!$J$11:$J$14,0)),"?") -> Marrocos | AN11: =IFERROR(INDEX(Calc!$H$11:$H$14,MATCH(2,Calc!$J$11:$J$14,0)),0) -> 6 | AO11: =IFERROR(INDEX(Calc!$K$11:$K$14,MATCH(2,Calc!$J$11:$J$14,0)),0) -> 3 | AP11: =IFERROR(INDEX(Calc!$C$11:$C$14,MATCH(2,Calc!$J$11:$J$14,0)),0) -> 2 | AQ11: =IFERROR(INDEX(Calc!$D$11:$D$14,MATCH(2,Calc!$J$11:$J$14,0)),0) -> 0 | AR11: =IFERROR(INDEX(Calc!$L$11:$L$14,MATCH(2,Calc!$J$11:$J$14,0)),0) -> 1 | AS11: =IFERROR(INDEX(Calc!$E$11:$E$14,MATCH(2,Calc!$J$11:$J$14,0)),0) -> 6 | AT11: =IFERROR(INDEX(Calc!$F$11:$F$14,MATCH(2,Calc!$J$11:$J$14,0)),0) -> 2 | AU11: =IFERROR(INDEX(Calc!$G$11:$G$14,MATCH(2,Calc!$J$11:$J$14,0)),0) -> 4 | AV11: =IFERROR(ROUND(INDEX(Calc!$H$11:$H$14,MATCH(2,Calc!$J$11:$J$14,0))/(INDEX(Calc!$K$11:$K$14,MATCH(2,Calc!$J$11:$J$14,0))*3)*100,0),0) -> 67
A12: 3 | B12: =IFERROR(INDEX(Calc!$B$3:$B$6,MATCH(3,Calc!$J$3:$J$6,0)),"?") -> Coreia do Sul | H12: =IFERROR(INDEX(Calc!$H$3:$H$6,MATCH(3,Calc!$J$3:$J$6,0)),0) -> 4 | I12: =IFERROR(INDEX(Calc!$K$3:$K$6,MATCH(3,Calc!$J$3:$J$6,0)),0) -> 3 | J12: =IFERROR(INDEX(Calc!$C$3:$C$6,MATCH(3,Calc!$J$3:$J$6,0)),0) -> 1 | K12: =IFERROR(INDEX(Calc!$D$3:$D$6,MATCH(3,Calc!$J$3:$J$6,0)),0) -> 1 | L12: =IFERROR(INDEX(Calc!$L$3:$L$6,MATCH(3,Calc!$J$3:$J$6,0)),0) -> 1 | M12: =IFERROR(INDEX(Calc!$E$3:$E$6,MATCH(3,Calc!$J$3:$J$6,0)),0) -> 4 | N12: =IFERROR(INDEX(Calc!$F$3:$F$6,MATCH(3,Calc!$J$3:$J$6,0)),0) -> 4 | O12: =IFERROR(INDEX(Calc!$G$3:$G$6,MATCH(3,Calc!$J$3:$J$6,0)),0) -> 0 | P12: =IFERROR(ROUND(INDEX(Calc!$H$3:$H$6,MATCH(3,Calc!$J$3:$J$6,0))/(INDEX(Calc!$K$3:$K$6,MATCH(3,Calc!$J$3:$J$6,0))*3)*100,0),0) -> 44 | Q12: 3 | R12: =IFERROR(INDEX(Calc!$B$7:$B$10,MATCH(3,Calc!$J$7:$J$10,0)),"?") -> Bosnia e Herzegovina | X12: =IFERROR(INDEX(Calc!$H$7:$H$10,MATCH(3,Calc!$J$7:$J$10,0)),0) -> 2 | Y12: =IFERROR(INDEX(Calc!$K$7:$K$10,MATCH(3,Calc!$J$7:$J$10,0)),0) -> 3 | Z12: =IFERROR(INDEX(Calc!$C$7:$C$10,MATCH(3,Calc!$J$7:$J$10,0)),0) -> 0 | AA12: =IFERROR(INDEX(Calc!$D$7:$D$10,MATCH(3,Calc!$J$7:$J$10,0)),0) -> 2 | AB12: =IFERROR(INDEX(Calc!$L$7:$L$10,MATCH(3,Calc!$J$7:$J$10,0)),0) -> 1 | AC12: =IFERROR(INDEX(Calc!$E$7:$E$10,MATCH(3,Calc!$J$7:$J$10,0)),0) -> 4 | AD12: =IFERROR(INDEX(Calc!$F$7:$F$10,MATCH(3,Calc!$J$7:$J$10,0)),0) -> 6 | AE12: =IFERROR(INDEX(Calc!$G$7:$G$10,MATCH(3,Calc!$J$7:$J$10,0)),0) -> -2 | AF12: =IFERROR(ROUND(INDEX(Calc!$H$7:$H$10,MATCH(3,Calc!$J$7:$J$10,0))/(INDEX(Calc!$K$7:$K$10,MATCH(3,Calc!$J$7:$J$10,0))*3)*100,0),0) -> 22 | AG12: 3 | AH12: =IFERROR(INDEX(Calc!$B$11:$B$14,MATCH(3,Calc!$J$11:$J$14,0)),"?") -> Escocia | AN12: =IFERROR(INDEX(Calc!$H$11:$H$14,MATCH(3,Calc!$J$11:$J$14,0)),0) -> 3 | AO12: =IFERROR(INDEX(Calc!$K$11:$K$14,MATCH(3,Calc!$J$11:$J$14,0)),0) -> 3 | AP12: =IFERROR(INDEX(Calc!$C$11:$C$14,MATCH(3,Calc!$J$11:$J$14,0)),0) -> 1 | AQ12: =IFERROR(INDEX(Calc!$D$11:$D$14,MATCH(3,Calc!$J$11:$J$14,0)),0) -> 0 | AR12: =IFERROR(INDEX(Calc!$L$11:$L$14,MATCH(3,Calc!$J$11:$J$14,0)),0) -> 2 | AS12: =IFERROR(INDEX(Calc!$E$11:$E$14,MATCH(3,Calc!$J$11:$J$14,0)),0) -> 3 | AT12: =IFERROR(INDEX(Calc!$F$11:$F$14,MATCH(3,Calc!$J$11:$J$14,0)),0) -> 4 | AU12: =IFERROR(INDEX(Calc!$G$11:$G$14,MATCH(3,Calc!$J$11:$J$14,0)),0) -> -1 | AV12: =IFERROR(ROUND(INDEX(Calc!$H$11:$H$14,MATCH(3,Calc!$J$11:$J$14,0))/(INDEX(Calc!$K$11:$K$14,MATCH(3,Calc!$J$11:$J$14,0))*3)*100,0),0) -> 33
A13: 4 | B13: =IFERROR(INDEX(Calc!$B$3:$B$6,MATCH(4,Calc!$J$3:$J$6,0)),"?") -> Africa do Sul | H13: =IFERROR(INDEX(Calc!$H$3:$H$6,MATCH(4,Calc!$J$3:$J$6,0)),0) -> 0 | I13: =IFERROR(INDEX(Calc!$K$3:$K$6,MATCH(4,Calc!$J$3:$J$6,0)),0) -> 3 | J13: =IFERROR(INDEX(Calc!$C$3:$C$6,MATCH(4,Calc!$J$3:$J$6,0)),0) -> 0 | K13: =IFERROR(INDEX(Calc!$D$3:$D$6,MATCH(4,Calc!$J$3:$J$6,0)),0) -> 0 | L13: =IFERROR(INDEX(Calc!$L$3:$L$6,MATCH(4,Calc!$J$3:$J$6,0)),0) -> 3 | M13: =IFERROR(INDEX(Calc!$E$3:$E$6,MATCH(4,Calc!$J$3:$J$6,0)),0) -> 2 | N13: =IFERROR(INDEX(Calc!$F$3:$F$6,MATCH(4,Calc!$J$3:$J$6,0)),0) -> 7 | O13: =IFERROR(INDEX(Calc!$G$3:$G$6,MATCH(4,Calc!$J$3:$J$6,0)),0) -> -5 | P13: =IFERROR(ROUND(INDEX(Calc!$H$3:$H$6,MATCH(4,Calc!$J$3:$J$6,0))/(INDEX(Calc!$K$3:$K$6,MATCH(4,Calc!$J$3:$J$6,0))*3)*100,0),0) -> 0 | Q13: 4 | R13: =IFERROR(INDEX(Calc!$B$7:$B$10,MATCH(4,Calc!$J$7:$J$10,0)),"?") -> Qatar | X13: =IFERROR(INDEX(Calc!$H$7:$H$10,MATCH(4,Calc!$J$7:$J$10,0)),0) -> 1 | Y13: =IFERROR(INDEX(Calc!$K$7:$K$10,MATCH(4,Calc!$J$7:$J$10,0)),0) -> 3 | Z13: =IFERROR(INDEX(Calc!$C$7:$C$10,MATCH(4,Calc!$J$7:$J$10,0)),0) -> 0 | AA13: =IFERROR(INDEX(Calc!$D$7:$D$10,MATCH(4,Calc!$J$7:$J$10,0)),0) -> 1 | AB13: =IFERROR(INDEX(Calc!$L$7:$L$10,MATCH(4,Calc!$J$7:$J$10,0)),0) -> 2 | AC13: =IFERROR(INDEX(Calc!$E$7:$E$10,MATCH(4,Calc!$J$7:$J$10,0)),0) -> 2 | AD13: =IFERROR(INDEX(Calc!$F$7:$F$10,MATCH(4,Calc!$J$7:$J$10,0)),0) -> 6 | AE13: =IFERROR(INDEX(Calc!$G$7:$G$10,MATCH(4,Calc!$J$7:$J$10,0)),0) -> -4 | AF13: =IFERROR(ROUND(INDEX(Calc!$H$7:$H$10,MATCH(4,Calc!$J$7:$J$10,0))/(INDEX(Calc!$K$7:$K$10,MATCH(4,Calc!$J$7:$J$10,0))*3)*100,0),0) -> 11 | AG13: 4 | AH13: =IFERROR(INDEX(Calc!$B$11:$B$14,MATCH(4,Calc!$J$11:$J$14,0)),"?") -> Haiti | AN13: =IFERROR(INDEX(Calc!$H$11:$H$14,MATCH(4,Calc!$J$11:$J$14,0)),0) -> 0 | AO13: =IFERROR(INDEX(Calc!$K$11:$K$14,MATCH(4,Calc!$J$11:$J$14,0)),0) -> 3 | AP13: =IFERROR(INDEX(Calc!$C$11:$C$14,MATCH(4,Calc!$J$11:$J$14,0)),0) -> 0 | AQ13: =IFERROR(INDEX(Calc!$D$11:$D$14,MATCH(4,Calc!$J$11:$J$14,0)),0) -> 0 | AR13: =IFERROR(INDEX(Calc!$L$11:$L$14,MATCH(4,Calc!$J$11:$J$14,0)),0) -> 3 | AS13: =IFERROR(INDEX(Calc!$E$11:$E$14,MATCH(4,Calc!$J$11:$J$14,0)),0) -> 0 | AT13: =IFERROR(INDEX(Calc!$F$11:$F$14,MATCH(4,Calc!$J$11:$J$14,0)),0) -> 10 | AU13: =IFERROR(INDEX(Calc!$G$11:$G$14,MATCH(4,Calc!$J$11:$J$14,0)),0) -> -10 | AV13: =IFERROR(ROUND(INDEX(Calc!$H$11:$H$14,MATCH(4,Calc!$J$11:$J$14,0))/(INDEX(Calc!$K$11:$K$14,MATCH(4,Calc!$J$11:$J$14,0))*3)*100,0),0) -> 0
A15: Grupo D | Q15: Grupo E | AG15: Grupo F
A16: # | B16: Seleção | H16: P | I16: J | J16: V | K16: E | L16: D | M16: GP | N16: GC | O16: SG | P16: % | Q16: # | R16: Seleção | X16: P | Y16: J | Z16: V | AA16: E | AB16: D | AC16: GP | AD16: GC | AE16: SG | AF16: % | AG16: # | AH16: Seleção | AN16: P | AO16: J | AP16: V | AQ16: E | AR16: D | AS16: GP | AT16: GC | AU16: SG | AV16: %
A17: 1 | B17: =IFERROR(INDEX(Calc!$B$15:$B$18,MATCH(1,Calc!$J$15:$J$18,0)),"?") -> Estados Unidos | H17: =IFERROR(INDEX(Calc!$H$15:$H$18,MATCH(1,Calc!$J$15:$J$18,0)),0) -> 5 | I17: =IFERROR(INDEX(Calc!$K$15:$K$18,MATCH(1,Calc!$J$15:$J$18,0)),0) -> 3 | J17: =IFERROR(INDEX(Calc!$C$15:$C$18,MATCH(1,Calc!$J$15:$J$18,0)),0) -> 1 | K17: =IFERROR(INDEX(Calc!$D$15:$D$18,MATCH(1,Calc!$J$15:$J$18,0)),0) -> 2 | L17: =IFERROR(INDEX(Calc!$L$15:$L$18,MATCH(1,Calc!$J$15:$J$18,0)),0) -> 0 | M17: =IFERROR(INDEX(Calc!$E$15:$E$18,MATCH(1,Calc!$J$15:$J$18,0)),0) -> 4 | N17: =IFERROR(INDEX(Calc!$F$15:$F$18,MATCH(1,Calc!$J$15:$J$18,0)),0) -> 2 | O17: =IFERROR(INDEX(Calc!$G$15:$G$18,MATCH(1,Calc!$J$15:$J$18,0)),0) -> 2 | P17: =IFERROR(ROUND(INDEX(Calc!$H$15:$H$18,MATCH(1,Calc!$J$15:$J$18,0))/(INDEX(Calc!$K$15:$K$18,MATCH(1,Calc!$J$15:$J$18,0))*3)*100,0),0) -> 56 | Q17: 1 | R17: =IFERROR(INDEX(Calc!$B$19:$B$22,MATCH(1,Calc!$J$19:$J$22,0)),"?") -> Alemanha | X17: =IFERROR(INDEX(Calc!$H$19:$H$22,MATCH(1,Calc!$J$19:$J$22,0)),0) -> 9 | Y17: =IFERROR(INDEX(Calc!$K$19:$K$22,MATCH(1,Calc!$J$19:$J$22,0)),0) -> 3 | Z17: =IFERROR(INDEX(Calc!$C$19:$C$22,MATCH(1,Calc!$J$19:$J$22,0)),0) -> 3 | AA17: =IFERROR(INDEX(Calc!$D$19:$D$22,MATCH(1,Calc!$J$19:$J$22,0)),0) -> 0 | AB17: =IFERROR(INDEX(Calc!$L$19:$L$22,MATCH(1,Calc!$J$19:$J$22,0)),0) -> 0 | AC17: =IFERROR(INDEX(Calc!$E$19:$E$22,MATCH(1,Calc!$J$19:$J$22,0)),0) -> 8 | AD17: =IFERROR(INDEX(Calc!$F$19:$F$22,MATCH(1,Calc!$J$19:$J$22,0)),0) -> 2 | AE17: =IFERROR(INDEX(Calc!$G$19:$G$22,MATCH(1,Calc!$J$19:$J$22,0)),0) -> 6 | AF17: =IFERROR(ROUND(INDEX(Calc!$H$19:$H$22,MATCH(1,Calc!$J$19:$J$22,0))/(INDEX(Calc!$K$19:$K$22,MATCH(1,Calc!$J$19:$J$22,0))*3)*100,0),0) -> 100 | AG17: 1 | AH17: =IFERROR(INDEX(Calc!$B$23:$B$26,MATCH(1,Calc!$J$23:$J$26,0)),"?") -> Japao | AN17: =IFERROR(INDEX(Calc!$H$23:$H$26,MATCH(1,Calc!$J$23:$J$26,0)),0) -> 7 | AO17: =IFERROR(INDEX(Calc!$K$23:$K$26,MATCH(1,Calc!$J$23:$J$26,0)),0) -> 3 | AP17: =IFERROR(INDEX(Calc!$C$23:$C$26,MATCH(1,Calc!$J$23:$J$26,0)),0) -> 2 | AQ17: =IFERROR(INDEX(Calc!$D$23:$D$26,MATCH(1,Calc!$J$23:$J$26,0)),0) -> 1 | AR17: =IFERROR(INDEX(Calc!$L$23:$L$26,MATCH(1,Calc!$J$23:$J$26,0)),0) -> 0 | AS17: =IFERROR(INDEX(Calc!$E$23:$E$26,MATCH(1,Calc!$J$23:$J$26,0)),0) -> 6 | AT17: =IFERROR(INDEX(Calc!$F$23:$F$26,MATCH(1,Calc!$J$23:$J$26,0)),0) -> 1 | AU17: =IFERROR(INDEX(Calc!$G$23:$G$26,MATCH(1,Calc!$J$23:$J$26,0)),0) -> 5 | AV17: =IFERROR(ROUND(INDEX(Calc!$H$23:$H$26,MATCH(1,Calc!$J$23:$J$26,0))/(INDEX(Calc!$K$23:$K$26,MATCH(1,Calc!$J$23:$J$26,0))*3)*100,0),0) -> 78
A18: 2 | B18: =IFERROR(INDEX(Calc!$B$15:$B$18,MATCH(2,Calc!$J$15:$J$18,0)),"?") -> Turquia | H18: =IFERROR(INDEX(Calc!$H$15:$H$18,MATCH(2,Calc!$J$15:$J$18,0)),0) -> 5 | I18: =IFERROR(INDEX(Calc!$K$15:$K$18,MATCH(2,Calc!$J$15:$J$18,0)),0) -> 3 | J18: =IFERROR(INDEX(Calc!$C$15:$C$18,MATCH(2,Calc!$J$15:$J$18,0)),0) -> 1 | K18: =IFERROR(INDEX(Calc!$D$15:$D$18,MATCH(2,Calc!$J$15:$J$18,0)),0) -> 2 | L18: =IFERROR(INDEX(Calc!$L$15:$L$18,MATCH(2,Calc!$J$15:$J$18,0)),0) -> 0 | M18: =IFERROR(INDEX(Calc!$E$15:$E$18,MATCH(2,Calc!$J$15:$J$18,0)),0) -> 4 | N18: =IFERROR(INDEX(Calc!$F$15:$F$18,MATCH(2,Calc!$J$15:$J$18,0)),0) -> 2 | O18: =IFERROR(INDEX(Calc!$G$15:$G$18,MATCH(2,Calc!$J$15:$J$18,0)),0) -> 2 | P18: =IFERROR(ROUND(INDEX(Calc!$H$15:$H$18,MATCH(2,Calc!$J$15:$J$18,0))/(INDEX(Calc!$K$15:$K$18,MATCH(2,Calc!$J$15:$J$18,0))*3)*100,0),0) -> 56 | Q18: 2 | R18: =IFERROR(INDEX(Calc!$B$19:$B$22,MATCH(2,Calc!$J$19:$J$22,0)),"?") -> Equador | X18: =IFERROR(INDEX(Calc!$H$19:$H$22,MATCH(2,Calc!$J$19:$J$22,0)),0) -> 4 | Y18: =IFERROR(INDEX(Calc!$K$19:$K$22,MATCH(2,Calc!$J$19:$J$22,0)),0) -> 3 | Z18: =IFERROR(INDEX(Calc!$C$19:$C$22,MATCH(2,Calc!$J$19:$J$22,0)),0) -> 1 | AA18: =IFERROR(INDEX(Calc!$D$19:$D$22,MATCH(2,Calc!$J$19:$J$22,0)),0) -> 1 | AB18: =IFERROR(INDEX(Calc!$L$19:$L$22,MATCH(2,Calc!$J$19:$J$22,0)),0) -> 1 | AC18: =IFERROR(INDEX(Calc!$E$19:$E$22,MATCH(2,Calc!$J$19:$J$22,0)),0) -> 5 | AD18: =IFERROR(INDEX(Calc!$F$19:$F$22,MATCH(2,Calc!$J$19:$J$22,0)),0) -> 4 | AE18: =IFERROR(INDEX(Calc!$G$19:$G$22,MATCH(2,Calc!$J$19:$J$22,0)),0) -> 1 | AF18: =IFERROR(ROUND(INDEX(Calc!$H$19:$H$22,MATCH(2,Calc!$J$19:$J$22,0))/(INDEX(Calc!$K$19:$K$22,MATCH(2,Calc!$J$19:$J$22,0))*3)*100,0),0) -> 44 | AG18: 2 | AH18: =IFERROR(INDEX(Calc!$B$23:$B$26,MATCH(2,Calc!$J$23:$J$26,0)),"?") -> Holanda | AN18: =IFERROR(INDEX(Calc!$H$23:$H$26,MATCH(2,Calc!$J$23:$J$26,0)),0) -> 5 | AO18: =IFERROR(INDEX(Calc!$K$23:$K$26,MATCH(2,Calc!$J$23:$J$26,0)),0) -> 3 | AP18: =IFERROR(INDEX(Calc!$C$23:$C$26,MATCH(2,Calc!$J$23:$J$26,0)),0) -> 1 | AQ18: =IFERROR(INDEX(Calc!$D$23:$D$26,MATCH(2,Calc!$J$23:$J$26,0)),0) -> 2 | AR18: =IFERROR(INDEX(Calc!$L$23:$L$26,MATCH(2,Calc!$J$23:$J$26,0)),0) -> 0 | AS18: =IFERROR(INDEX(Calc!$E$23:$E$26,MATCH(2,Calc!$J$23:$J$26,0)),0) -> 5 | AT18: =IFERROR(INDEX(Calc!$F$23:$F$26,MATCH(2,Calc!$J$23:$J$26,0)),0) -> 3 | AU18: =IFERROR(INDEX(Calc!$G$23:$G$26,MATCH(2,Calc!$J$23:$J$26,0)),0) -> 2 | AV18: =IFERROR(ROUND(INDEX(Calc!$H$23:$H$26,MATCH(2,Calc!$J$23:$J$26,0))/(INDEX(Calc!$K$23:$K$26,MATCH(2,Calc!$J$23:$J$26,0))*3)*100,0),0) -> 56
A19: 3 | B19: =IFERROR(INDEX(Calc!$B$15:$B$18,MATCH(3,Calc!$J$15:$J$18,0)),"?") -> Paraguai | H19: =IFERROR(INDEX(Calc!$H$15:$H$18,MATCH(3,Calc!$J$15:$J$18,0)),0) -> 5 | I19: =IFERROR(INDEX(Calc!$K$15:$K$18,MATCH(3,Calc!$J$15:$J$18,0)),0) -> 3 | J19: =IFERROR(INDEX(Calc!$C$15:$C$18,MATCH(3,Calc!$J$15:$J$18,0)),0) -> 1 | K19: =IFERROR(INDEX(Calc!$D$15:$D$18,MATCH(3,Calc!$J$15:$J$18,0)),0) -> 2 | L19: =IFERROR(INDEX(Calc!$L$15:$L$18,MATCH(3,Calc!$J$15:$J$18,0)),0) -> 0 | M19: =IFERROR(INDEX(Calc!$E$15:$E$18,MATCH(3,Calc!$J$15:$J$18,0)),0) -> 4 | N19: =IFERROR(INDEX(Calc!$F$15:$F$18,MATCH(3,Calc!$J$15:$J$18,0)),0) -> 2 | O19: =IFERROR(INDEX(Calc!$G$15:$G$18,MATCH(3,Calc!$J$15:$J$18,0)),0) -> 2 | P19: =IFERROR(ROUND(INDEX(Calc!$H$15:$H$18,MATCH(3,Calc!$J$15:$J$18,0))/(INDEX(Calc!$K$15:$K$18,MATCH(3,Calc!$J$15:$J$18,0))*3)*100,0),0) -> 56 | Q19: 3 | R19: =IFERROR(INDEX(Calc!$B$19:$B$22,MATCH(3,Calc!$J$19:$J$22,0)),"?") -> Costa do Marfim | X19: =IFERROR(INDEX(Calc!$H$19:$H$22,MATCH(3,Calc!$J$19:$J$22,0)),0) -> 4 | Y19: =IFERROR(INDEX(Calc!$K$19:$K$22,MATCH(3,Calc!$J$19:$J$22,0)),0) -> 3 | Z19: =IFERROR(INDEX(Calc!$C$19:$C$22,MATCH(3,Calc!$J$19:$J$22,0)),0) -> 1 | AA19: =IFERROR(INDEX(Calc!$D$19:$D$22,MATCH(3,Calc!$J$19:$J$22,0)),0) -> 1 | AB19: =IFERROR(INDEX(Calc!$L$19:$L$22,MATCH(3,Calc!$J$19:$J$22,0)),0) -> 1 | AC19: =IFERROR(INDEX(Calc!$E$19:$E$22,MATCH(3,Calc!$J$19:$J$22,0)),0) -> 4 | AD19: =IFERROR(INDEX(Calc!$F$19:$F$22,MATCH(3,Calc!$J$19:$J$22,0)),0) -> 3 | AE19: =IFERROR(INDEX(Calc!$G$19:$G$22,MATCH(3,Calc!$J$19:$J$22,0)),0) -> 1 | AF19: =IFERROR(ROUND(INDEX(Calc!$H$19:$H$22,MATCH(3,Calc!$J$19:$J$22,0))/(INDEX(Calc!$K$19:$K$22,MATCH(3,Calc!$J$19:$J$22,0))*3)*100,0),0) -> 44 | AG19: 3 | AH19: =IFERROR(INDEX(Calc!$B$23:$B$26,MATCH(3,Calc!$J$23:$J$26,0)),"?") -> Suecia | AN19: =IFERROR(INDEX(Calc!$H$23:$H$26,MATCH(3,Calc!$J$23:$J$26,0)),0) -> 4 | AO19: =IFERROR(INDEX(Calc!$K$23:$K$26,MATCH(3,Calc!$J$23:$J$26,0)),0) -> 3 | AP19: =IFERROR(INDEX(Calc!$C$23:$C$26,MATCH(3,Calc!$J$23:$J$26,0)),0) -> 1 | AQ19: =IFERROR(INDEX(Calc!$D$23:$D$26,MATCH(3,Calc!$J$23:$J$26,0)),0) -> 1 | AR19: =IFERROR(INDEX(Calc!$L$23:$L$26,MATCH(3,Calc!$J$23:$J$26,0)),0) -> 1 | AS19: =IFERROR(INDEX(Calc!$E$23:$E$26,MATCH(3,Calc!$J$23:$J$26,0)),0) -> 4 | AT19: =IFERROR(INDEX(Calc!$F$23:$F$26,MATCH(3,Calc!$J$23:$J$26,0)),0) -> 5 | AU19: =IFERROR(INDEX(Calc!$G$23:$G$26,MATCH(3,Calc!$J$23:$J$26,0)),0) -> -1 | AV19: =IFERROR(ROUND(INDEX(Calc!$H$23:$H$26,MATCH(3,Calc!$J$23:$J$26,0))/(INDEX(Calc!$K$23:$K$26,MATCH(3,Calc!$J$23:$J$26,0))*3)*100,0),0) -> 44
A20: 4 | B20: =IFERROR(INDEX(Calc!$B$15:$B$18,MATCH(4,Calc!$J$15:$J$18,0)),"?") -> Australia | H20: =IFERROR(INDEX(Calc!$H$15:$H$18,MATCH(4,Calc!$J$15:$J$18,0)),0) -> 0 | I20: =IFERROR(INDEX(Calc!$K$15:$K$18,MATCH(4,Calc!$J$15:$J$18,0)),0) -> 3 | J20: =IFERROR(INDEX(Calc!$C$15:$C$18,MATCH(4,Calc!$J$15:$J$18,0)),0) -> 0 | K20: =IFERROR(INDEX(Calc!$D$15:$D$18,MATCH(4,Calc!$J$15:$J$18,0)),0) -> 0 | L20: =IFERROR(INDEX(Calc!$L$15:$L$18,MATCH(4,Calc!$J$15:$J$18,0)),0) -> 3 | M20: =IFERROR(INDEX(Calc!$E$15:$E$18,MATCH(4,Calc!$J$15:$J$18,0)),0) -> 2 | N20: =IFERROR(INDEX(Calc!$F$15:$F$18,MATCH(4,Calc!$J$15:$J$18,0)),0) -> 8 | O20: =IFERROR(INDEX(Calc!$G$15:$G$18,MATCH(4,Calc!$J$15:$J$18,0)),0) -> -6 | P20: =IFERROR(ROUND(INDEX(Calc!$H$15:$H$18,MATCH(4,Calc!$J$15:$J$18,0))/(INDEX(Calc!$K$15:$K$18,MATCH(4,Calc!$J$15:$J$18,0))*3)*100,0),0) -> 0 | Q20: 4 | R20: =IFERROR(INDEX(Calc!$B$19:$B$22,MATCH(4,Calc!$J$19:$J$22,0)),"?") -> Curacao | X20: =IFERROR(INDEX(Calc!$H$19:$H$22,MATCH(4,Calc!$J$19:$J$22,0)),0) -> 0 | Y20: =IFERROR(INDEX(Calc!$K$19:$K$22,MATCH(4,Calc!$J$19:$J$22,0)),0) -> 3 | Z20: =IFERROR(INDEX(Calc!$C$19:$C$22,MATCH(4,Calc!$J$19:$J$22,0)),0) -> 0 | AA20: =IFERROR(INDEX(Calc!$D$19:$D$22,MATCH(4,Calc!$J$19:$J$22,0)),0) -> 0 | AB20: =IFERROR(INDEX(Calc!$L$19:$L$22,MATCH(4,Calc!$J$19:$J$22,0)),0) -> 3 | AC20: =IFERROR(INDEX(Calc!$E$19:$E$22,MATCH(4,Calc!$J$19:$J$22,0)),0) -> 0 | AD20: =IFERROR(INDEX(Calc!$F$19:$F$22,MATCH(4,Calc!$J$19:$J$22,0)),0) -> 8 | AE20: =IFERROR(INDEX(Calc!$G$19:$G$22,MATCH(4,Calc!$J$19:$J$22,0)),0) -> -8 | AF20: =IFERROR(ROUND(INDEX(Calc!$H$19:$H$22,MATCH(4,Calc!$J$19:$J$22,0))/(INDEX(Calc!$K$19:$K$22,MATCH(4,Calc!$J$19:$J$22,0))*3)*100,0),0) -> 0 | AG20: 4 | AH20: =IFERROR(INDEX(Calc!$B$23:$B$26,MATCH(4,Calc!$J$23:$J$26,0)),"?") -> Tunisia | AN20: =IFERROR(INDEX(Calc!$H$23:$H$26,MATCH(4,Calc!$J$23:$J$26,0)),0) -> 0 | AO20: =IFERROR(INDEX(Calc!$K$23:$K$26,MATCH(4,Calc!$J$23:$J$26,0)),0) -> 3 | AP20: =IFERROR(INDEX(Calc!$C$23:$C$26,MATCH(4,Calc!$J$23:$J$26,0)),0) -> 0 | AQ20: =IFERROR(INDEX(Calc!$D$23:$D$26,MATCH(4,Calc!$J$23:$J$26,0)),0) -> 0 | AR20: =IFERROR(INDEX(Calc!$L$23:$L$26,MATCH(4,Calc!$J$23:$J$26,0)),0) -> 3 | AS20: =IFERROR(INDEX(Calc!$E$23:$E$26,MATCH(4,Calc!$J$23:$J$26,0)),0) -> 1 | AT20: =IFERROR(INDEX(Calc!$F$23:$F$26,MATCH(4,Calc!$J$23:$J$26,0)),0) -> 7 | AU20: =IFERROR(INDEX(Calc!$G$23:$G$26,MATCH(4,Calc!$J$23:$J$26,0)),0) -> -6 | AV20: =IFERROR(ROUND(INDEX(Calc!$H$23:$H$26,MATCH(4,Calc!$J$23:$J$26,0))/(INDEX(Calc!$K$23:$K$26,MATCH(4,Calc!$J$23:$J$26,0))*3)*100,0),0) -> 0
A22: Grupo G | Q22: Grupo H | AG22: Grupo I
A23: # | B23: Seleção | H23: P | I23: J | J23: V | K23: E | L23: D | M23: GP | N23: GC | O23: SG | P23: % | Q23: # | R23: Seleção | X23: P | Y23: J | Z23: V | AA23: E | AB23: D | AC23: GP | AD23: GC | AE23: SG | AF23: % | AG23: # | AH23: Seleção | AN23: P | AO23: J | AP23: V | AQ23: E | AR23: D | AS23: GP | AT23: GC | AU23: SG | AV23: %
A24: 1 | B24: =IFERROR(INDEX(Calc!$B$27:$B$30,MATCH(1,Calc!$J$27:$J$30,0)),"?") -> Belgica | H24: =IFERROR(INDEX(Calc!$H$27:$H$30,MATCH(1,Calc!$J$27:$J$30,0)),0) -> 9 | I24: =IFERROR(INDEX(Calc!$K$27:$K$30,MATCH(1,Calc!$J$27:$J$30,0)),0) -> 3 | J24: =IFERROR(INDEX(Calc!$C$27:$C$30,MATCH(1,Calc!$J$27:$J$30,0)),0) -> 3 | K24: =IFERROR(INDEX(Calc!$D$27:$D$30,MATCH(1,Calc!$J$27:$J$30,0)),0) -> 0 | L24: =IFERROR(INDEX(Calc!$L$27:$L$30,MATCH(1,Calc!$J$27:$J$30,0)),0) -> 0 | M24: =IFERROR(INDEX(Calc!$E$27:$E$30,MATCH(1,Calc!$J$27:$J$30,0)),0) -> 9 | N24: =IFERROR(INDEX(Calc!$F$27:$F$30,MATCH(1,Calc!$J$27:$J$30,0)),0) -> 2 | O24: =IFERROR(INDEX(Calc!$G$27:$G$30,MATCH(1,Calc!$J$27:$J$30,0)),0) -> 7 | P24: =IFERROR(ROUND(INDEX(Calc!$H$27:$H$30,MATCH(1,Calc!$J$27:$J$30,0))/(INDEX(Calc!$K$27:$K$30,MATCH(1,Calc!$J$27:$J$30,0))*3)*100,0),0) -> 100 | Q24: 1 | R24: =IFERROR(INDEX(Calc!$B$31:$B$34,MATCH(1,Calc!$J$31:$J$34,0)),"?") -> Espanha | X24: =IFERROR(INDEX(Calc!$H$31:$H$34,MATCH(1,Calc!$J$31:$J$34,0)),0) -> 9 | Y24: =IFERROR(INDEX(Calc!$K$31:$K$34,MATCH(1,Calc!$J$31:$J$34,0)),0) -> 3 | Z24: =IFERROR(INDEX(Calc!$C$31:$C$34,MATCH(1,Calc!$J$31:$J$34,0)),0) -> 3 | AA24: =IFERROR(INDEX(Calc!$D$31:$D$34,MATCH(1,Calc!$J$31:$J$34,0)),0) -> 0 | AB24: =IFERROR(INDEX(Calc!$L$31:$L$34,MATCH(1,Calc!$J$31:$J$34,0)),0) -> 0 | AC24: =IFERROR(INDEX(Calc!$E$31:$E$34,MATCH(1,Calc!$J$31:$J$34,0)),0) -> 9 | AD24: =IFERROR(INDEX(Calc!$F$31:$F$34,MATCH(1,Calc!$J$31:$J$34,0)),0) -> 2 | AE24: =IFERROR(INDEX(Calc!$G$31:$G$34,MATCH(1,Calc!$J$31:$J$34,0)),0) -> 7 | AF24: =IFERROR(ROUND(INDEX(Calc!$H$31:$H$34,MATCH(1,Calc!$J$31:$J$34,0))/(INDEX(Calc!$K$31:$K$34,MATCH(1,Calc!$J$31:$J$34,0))*3)*100,0),0) -> 100 | AG24: 1 | AH24: =IFERROR(INDEX(Calc!$B$35:$B$38,MATCH(1,Calc!$J$35:$J$38,0)),"?") -> Franca | AN24: =IFERROR(INDEX(Calc!$H$35:$H$38,MATCH(1,Calc!$J$35:$J$38,0)),0) -> 9 | AO24: =IFERROR(INDEX(Calc!$K$35:$K$38,MATCH(1,Calc!$J$35:$J$38,0)),0) -> 3 | AP24: =IFERROR(INDEX(Calc!$C$35:$C$38,MATCH(1,Calc!$J$35:$J$38,0)),0) -> 3 | AQ24: =IFERROR(INDEX(Calc!$D$35:$D$38,MATCH(1,Calc!$J$35:$J$38,0)),0) -> 0 | AR24: =IFERROR(INDEX(Calc!$L$35:$L$38,MATCH(1,Calc!$J$35:$J$38,0)),0) -> 0 | AS24: =IFERROR(INDEX(Calc!$E$35:$E$38,MATCH(1,Calc!$J$35:$J$38,0)),0) -> 7 | AT24: =IFERROR(INDEX(Calc!$F$35:$F$38,MATCH(1,Calc!$J$35:$J$38,0)),0) -> 1 | AU24: =IFERROR(INDEX(Calc!$G$35:$G$38,MATCH(1,Calc!$J$35:$J$38,0)),0) -> 6 | AV24: =IFERROR(ROUND(INDEX(Calc!$H$35:$H$38,MATCH(1,Calc!$J$35:$J$38,0))/(INDEX(Calc!$K$35:$K$38,MATCH(1,Calc!$J$35:$J$38,0))*3)*100,0),0) -> 100
A25: 2 | B25: =IFERROR(INDEX(Calc!$B$27:$B$30,MATCH(2,Calc!$J$27:$J$30,0)),"?") -> Egito | H25: =IFERROR(INDEX(Calc!$H$27:$H$30,MATCH(2,Calc!$J$27:$J$30,0)),0) -> 4 | I25: =IFERROR(INDEX(Calc!$K$27:$K$30,MATCH(2,Calc!$J$27:$J$30,0)),0) -> 3 | J25: =IFERROR(INDEX(Calc!$C$27:$C$30,MATCH(2,Calc!$J$27:$J$30,0)),0) -> 1 | K25: =IFERROR(INDEX(Calc!$D$27:$D$30,MATCH(2,Calc!$J$27:$J$30,0)),0) -> 1 | L25: =IFERROR(INDEX(Calc!$L$27:$L$30,MATCH(2,Calc!$J$27:$J$30,0)),0) -> 1 | M25: =IFERROR(INDEX(Calc!$E$27:$E$30,MATCH(2,Calc!$J$27:$J$30,0)),0) -> 4 | N25: =IFERROR(INDEX(Calc!$F$27:$F$30,MATCH(2,Calc!$J$27:$J$30,0)),0) -> 4 | O25: =IFERROR(INDEX(Calc!$G$27:$G$30,MATCH(2,Calc!$J$27:$J$30,0)),0) -> 0 | P25: =IFERROR(ROUND(INDEX(Calc!$H$27:$H$30,MATCH(2,Calc!$J$27:$J$30,0))/(INDEX(Calc!$K$27:$K$30,MATCH(2,Calc!$J$27:$J$30,0))*3)*100,0),0) -> 44 | Q25: 2 | R25: =IFERROR(INDEX(Calc!$B$31:$B$34,MATCH(2,Calc!$J$31:$J$34,0)),"?") -> Uruguai | X25: =IFERROR(INDEX(Calc!$H$31:$H$34,MATCH(2,Calc!$J$31:$J$34,0)),0) -> 6 | Y25: =IFERROR(INDEX(Calc!$K$31:$K$34,MATCH(2,Calc!$J$31:$J$34,0)),0) -> 3 | Z25: =IFERROR(INDEX(Calc!$C$31:$C$34,MATCH(2,Calc!$J$31:$J$34,0)),0) -> 2 | AA25: =IFERROR(INDEX(Calc!$D$31:$D$34,MATCH(2,Calc!$J$31:$J$34,0)),0) -> 0 | AB25: =IFERROR(INDEX(Calc!$L$31:$L$34,MATCH(2,Calc!$J$31:$J$34,0)),0) -> 1 | AC25: =IFERROR(INDEX(Calc!$E$31:$E$34,MATCH(2,Calc!$J$31:$J$34,0)),0) -> 7 | AD25: =IFERROR(INDEX(Calc!$F$31:$F$34,MATCH(2,Calc!$J$31:$J$34,0)),0) -> 4 | AE25: =IFERROR(INDEX(Calc!$G$31:$G$34,MATCH(2,Calc!$J$31:$J$34,0)),0) -> 3 | AF25: =IFERROR(ROUND(INDEX(Calc!$H$31:$H$34,MATCH(2,Calc!$J$31:$J$34,0))/(INDEX(Calc!$K$31:$K$34,MATCH(2,Calc!$J$31:$J$34,0))*3)*100,0),0) -> 67 | AG25: 2 | AH25: =IFERROR(INDEX(Calc!$B$35:$B$38,MATCH(2,Calc!$J$35:$J$38,0)),"?") -> Noruega | AN25: =IFERROR(INDEX(Calc!$H$35:$H$38,MATCH(2,Calc!$J$35:$J$38,0)),0) -> 6 | AO25: =IFERROR(INDEX(Calc!$K$35:$K$38,MATCH(2,Calc!$J$35:$J$38,0)),0) -> 3 | AP25: =IFERROR(INDEX(Calc!$C$35:$C$38,MATCH(2,Calc!$J$35:$J$38,0)),0) -> 2 | AQ25: =IFERROR(INDEX(Calc!$D$35:$D$38,MATCH(2,Calc!$J$35:$J$38,0)),0) -> 0 | AR25: =IFERROR(INDEX(Calc!$L$35:$L$38,MATCH(2,Calc!$J$35:$J$38,0)),0) -> 1 | AS25: =IFERROR(INDEX(Calc!$E$35:$E$38,MATCH(2,Calc!$J$35:$J$38,0)),0) -> 5 | AT25: =IFERROR(INDEX(Calc!$F$35:$F$38,MATCH(2,Calc!$J$35:$J$38,0)),0) -> 3 | AU25: =IFERROR(INDEX(Calc!$G$35:$G$38,MATCH(2,Calc!$J$35:$J$38,0)),0) -> 2 | AV25: =IFERROR(ROUND(INDEX(Calc!$H$35:$H$38,MATCH(2,Calc!$J$35:$J$38,0))/(INDEX(Calc!$K$35:$K$38,MATCH(2,Calc!$J$35:$J$38,0))*3)*100,0),0) -> 67
A26: 3 | B26: =IFERROR(INDEX(Calc!$B$27:$B$30,MATCH(3,Calc!$J$27:$J$30,0)),"?") -> Nova Zelandia | H26: =IFERROR(INDEX(Calc!$H$27:$H$30,MATCH(3,Calc!$J$27:$J$30,0)),0) -> 4 | I26: =IFERROR(INDEX(Calc!$K$27:$K$30,MATCH(3,Calc!$J$27:$J$30,0)),0) -> 3 | J26: =IFERROR(INDEX(Calc!$C$27:$C$30,MATCH(3,Calc!$J$27:$J$30,0)),0) -> 1 | K26: =IFERROR(INDEX(Calc!$D$27:$D$30,MATCH(3,Calc!$J$27:$J$30,0)),0) -> 1 | L26: =IFERROR(INDEX(Calc!$L$27:$L$30,MATCH(3,Calc!$J$27:$J$30,0)),0) -> 1 | M26: =IFERROR(INDEX(Calc!$E$27:$E$30,MATCH(3,Calc!$J$27:$J$30,0)),0) -> 3 | N26: =IFERROR(INDEX(Calc!$F$27:$F$30,MATCH(3,Calc!$J$27:$J$30,0)),0) -> 4 | O26: =IFERROR(INDEX(Calc!$G$27:$G$30,MATCH(3,Calc!$J$27:$J$30,0)),0) -> -1 | P26: =IFERROR(ROUND(INDEX(Calc!$H$27:$H$30,MATCH(3,Calc!$J$27:$J$30,0))/(INDEX(Calc!$K$27:$K$30,MATCH(3,Calc!$J$27:$J$30,0))*3)*100,0),0) -> 44 | Q26: 3 | R26: =IFERROR(INDEX(Calc!$B$31:$B$34,MATCH(3,Calc!$J$31:$J$34,0)),"?") -> Arabia Saudita | X26: =IFERROR(INDEX(Calc!$H$31:$H$34,MATCH(3,Calc!$J$31:$J$34,0)),0) -> 1 | Y26: =IFERROR(INDEX(Calc!$K$31:$K$34,MATCH(3,Calc!$J$31:$J$34,0)),0) -> 3 | Z26: =IFERROR(INDEX(Calc!$C$31:$C$34,MATCH(3,Calc!$J$31:$J$34,0)),0) -> 0 | AA26: =IFERROR(INDEX(Calc!$D$31:$D$34,MATCH(3,Calc!$J$31:$J$34,0)),0) -> 1 | AB26: =IFERROR(INDEX(Calc!$L$31:$L$34,MATCH(3,Calc!$J$31:$J$34,0)),0) -> 2 | AC26: =IFERROR(INDEX(Calc!$E$31:$E$34,MATCH(3,Calc!$J$31:$J$34,0)),0) -> 1 | AD26: =IFERROR(INDEX(Calc!$F$31:$F$34,MATCH(3,Calc!$J$31:$J$34,0)),0) -> 5 | AE26: =IFERROR(INDEX(Calc!$G$31:$G$34,MATCH(3,Calc!$J$31:$J$34,0)),0) -> -4 | AF26: =IFERROR(ROUND(INDEX(Calc!$H$31:$H$34,MATCH(3,Calc!$J$31:$J$34,0))/(INDEX(Calc!$K$31:$K$34,MATCH(3,Calc!$J$31:$J$34,0))*3)*100,0),0) -> 11 | AG26: 3 | AH26: =IFERROR(INDEX(Calc!$B$35:$B$38,MATCH(3,Calc!$J$35:$J$38,0)),"?") -> Senegal | AN26: =IFERROR(INDEX(Calc!$H$35:$H$38,MATCH(3,Calc!$J$35:$J$38,0)),0) -> 3 | AO26: =IFERROR(INDEX(Calc!$K$35:$K$38,MATCH(3,Calc!$J$35:$J$38,0)),0) -> 3 | AP26: =IFERROR(INDEX(Calc!$C$35:$C$38,MATCH(3,Calc!$J$35:$J$38,0)),0) -> 1 | AQ26: =IFERROR(INDEX(Calc!$D$35:$D$38,MATCH(3,Calc!$J$35:$J$38,0)),0) -> 0 | AR26: =IFERROR(INDEX(Calc!$L$35:$L$38,MATCH(3,Calc!$J$35:$J$38,0)),0) -> 2 | AS26: =IFERROR(INDEX(Calc!$E$35:$E$38,MATCH(3,Calc!$J$35:$J$38,0)),0) -> 4 | AT26: =IFERROR(INDEX(Calc!$F$35:$F$38,MATCH(3,Calc!$J$35:$J$38,0)),0) -> 5 | AU26: =IFERROR(INDEX(Calc!$G$35:$G$38,MATCH(3,Calc!$J$35:$J$38,0)),0) -> -1 | AV26: =IFERROR(ROUND(INDEX(Calc!$H$35:$H$38,MATCH(3,Calc!$J$35:$J$38,0))/(INDEX(Calc!$K$35:$K$38,MATCH(3,Calc!$J$35:$J$38,0))*3)*100,0),0) -> 33
A27: 4 | B27: =IFERROR(INDEX(Calc!$B$27:$B$30,MATCH(4,Calc!$J$27:$J$30,0)),"?") -> Ira | H27: =IFERROR(INDEX(Calc!$H$27:$H$30,MATCH(4,Calc!$J$27:$J$30,0)),0) -> 0 | I27: =IFERROR(INDEX(Calc!$K$27:$K$30,MATCH(4,Calc!$J$27:$J$30,0)),0) -> 3 | J27: =IFERROR(INDEX(Calc!$C$27:$C$30,MATCH(4,Calc!$J$27:$J$30,0)),0) -> 0 | K27: =IFERROR(INDEX(Calc!$D$27:$D$30,MATCH(4,Calc!$J$27:$J$30,0)),0) -> 0 | L27: =IFERROR(INDEX(Calc!$L$27:$L$30,MATCH(4,Calc!$J$27:$J$30,0)),0) -> 3 | M27: =IFERROR(INDEX(Calc!$E$27:$E$30,MATCH(4,Calc!$J$27:$J$30,0)),0) -> 0 | N27: =IFERROR(INDEX(Calc!$F$27:$F$30,MATCH(4,Calc!$J$27:$J$30,0)),0) -> 6 | O27: =IFERROR(INDEX(Calc!$G$27:$G$30,MATCH(4,Calc!$J$27:$J$30,0)),0) -> -6 | P27: =IFERROR(ROUND(INDEX(Calc!$H$27:$H$30,MATCH(4,Calc!$J$27:$J$30,0))/(INDEX(Calc!$K$27:$K$30,MATCH(4,Calc!$J$27:$J$30,0))*3)*100,0),0) -> 0 | Q27: 4 | R27: =IFERROR(INDEX(Calc!$B$31:$B$34,MATCH(4,Calc!$J$31:$J$34,0)),"?") -> Cabo Verde | X27: =IFERROR(INDEX(Calc!$H$31:$H$34,MATCH(4,Calc!$J$31:$J$34,0)),0) -> 1 | Y27: =IFERROR(INDEX(Calc!$K$31:$K$34,MATCH(4,Calc!$J$31:$J$34,0)),0) -> 3 | Z27: =IFERROR(INDEX(Calc!$C$31:$C$34,MATCH(4,Calc!$J$31:$J$34,0)),0) -> 0 | AA27: =IFERROR(INDEX(Calc!$D$31:$D$34,MATCH(4,Calc!$J$31:$J$34,0)),0) -> 1 | AB27: =IFERROR(INDEX(Calc!$L$31:$L$34,MATCH(4,Calc!$J$31:$J$34,0)),0) -> 2 | AC27: =IFERROR(INDEX(Calc!$E$31:$E$34,MATCH(4,Calc!$J$31:$J$34,0)),0) -> 2 | AD27: =IFERROR(INDEX(Calc!$F$31:$F$34,MATCH(4,Calc!$J$31:$J$34,0)),0) -> 8 | AE27: =IFERROR(INDEX(Calc!$G$31:$G$34,MATCH(4,Calc!$J$31:$J$34,0)),0) -> -6 | AF27: =IFERROR(ROUND(INDEX(Calc!$H$31:$H$34,MATCH(4,Calc!$J$31:$J$34,0))/(INDEX(Calc!$K$31:$K$34,MATCH(4,Calc!$J$31:$J$34,0))*3)*100,0),0) -> 11 | AG27: 4 | AH27: =IFERROR(INDEX(Calc!$B$35:$B$38,MATCH(4,Calc!$J$35:$J$38,0)),"?") -> Iraque | AN27: =IFERROR(INDEX(Calc!$H$35:$H$38,MATCH(4,Calc!$J$35:$J$38,0)),0) -> 0 | AO27: =IFERROR(INDEX(Calc!$K$35:$K$38,MATCH(4,Calc!$J$35:$J$38,0)),0) -> 3 | AP27: =IFERROR(INDEX(Calc!$C$35:$C$38,MATCH(4,Calc!$J$35:$J$38,0)),0) -> 0 | AQ27: =IFERROR(INDEX(Calc!$D$35:$D$38,MATCH(4,Calc!$J$35:$J$38,0)),0) -> 0 | AR27: =IFERROR(INDEX(Calc!$L$35:$L$38,MATCH(4,Calc!$J$35:$J$38,0)),0) -> 3 | AS27: =IFERROR(INDEX(Calc!$E$35:$E$38,MATCH(4,Calc!$J$35:$J$38,0)),0) -> 1 | AT27: =IFERROR(INDEX(Calc!$F$35:$F$38,MATCH(4,Calc!$J$35:$J$38,0)),0) -> 8 | AU27: =IFERROR(INDEX(Calc!$G$35:$G$38,MATCH(4,Calc!$J$35:$J$38,0)),0) -> -7 | AV27: =IFERROR(ROUND(INDEX(Calc!$H$35:$H$38,MATCH(4,Calc!$J$35:$J$38,0))/(INDEX(Calc!$K$35:$K$38,MATCH(4,Calc!$J$35:$J$38,0))*3)*100,0),0) -> 0
A29: Grupo J | Q29: Grupo K | AG29: Grupo L
A30: # | B30: Seleção | H30: P | I30: J | J30: V | K30: E | L30: D | M30: GP | N30: GC | O30: SG | P30: % | Q30: # | R30: Seleção | X30: P | Y30: J | Z30: V | AA30: E | AB30: D | AC30: GP | AD30: GC | AE30: SG | AF30: % | AG30: # | AH30: Seleção | AN30: P | AO30: J | AP30: V | AQ30: E | AR30: D | AS30: GP | AT30: GC | AU30: SG | AV30: %
A31: 1 | B31: =IFERROR(INDEX(Calc!$B$39:$B$42,MATCH(1,Calc!$J$39:$J$42,0)),"?") -> Argentina | H31: =IFERROR(INDEX(Calc!$H$39:$H$42,MATCH(1,Calc!$J$39:$J$42,0)),0) -> 9 | I31: =IFERROR(INDEX(Calc!$K$39:$K$42,MATCH(1,Calc!$J$39:$J$42,0)),0) -> 3 | J31: =IFERROR(INDEX(Calc!$C$39:$C$42,MATCH(1,Calc!$J$39:$J$42,0)),0) -> 3 | K31: =IFERROR(INDEX(Calc!$D$39:$D$42,MATCH(1,Calc!$J$39:$J$42,0)),0) -> 0 | L31: =IFERROR(INDEX(Calc!$L$39:$L$42,MATCH(1,Calc!$J$39:$J$42,0)),0) -> 0 | M31: =IFERROR(INDEX(Calc!$E$39:$E$42,MATCH(1,Calc!$J$39:$J$42,0)),0) -> 7 | N31: =IFERROR(INDEX(Calc!$F$39:$F$42,MATCH(1,Calc!$J$39:$J$42,0)),0) -> 0 | O31: =IFERROR(INDEX(Calc!$G$39:$G$42,MATCH(1,Calc!$J$39:$J$42,0)),0) -> 7 | P31: =IFERROR(ROUND(INDEX(Calc!$H$39:$H$42,MATCH(1,Calc!$J$39:$J$42,0))/(INDEX(Calc!$K$39:$K$42,MATCH(1,Calc!$J$39:$J$42,0))*3)*100,0),0) -> 100 | Q31: 1 | R31: =IFERROR(INDEX(Calc!$B$43:$B$46,MATCH(1,Calc!$J$43:$J$46,0)),"?") -> Portugal | X31: =IFERROR(INDEX(Calc!$H$43:$H$46,MATCH(1,Calc!$J$43:$J$46,0)),0) -> 7 | Y31: =IFERROR(INDEX(Calc!$K$43:$K$46,MATCH(1,Calc!$J$43:$J$46,0)),0) -> 3 | Z31: =IFERROR(INDEX(Calc!$C$43:$C$46,MATCH(1,Calc!$J$43:$J$46,0)),0) -> 2 | AA31: =IFERROR(INDEX(Calc!$D$43:$D$46,MATCH(1,Calc!$J$43:$J$46,0)),0) -> 1 | AB31: =IFERROR(INDEX(Calc!$L$43:$L$46,MATCH(1,Calc!$J$43:$J$46,0)),0) -> 0 | AC31: =IFERROR(INDEX(Calc!$E$43:$E$46,MATCH(1,Calc!$J$43:$J$46,0)),0) -> 8 | AD31: =IFERROR(INDEX(Calc!$F$43:$F$46,MATCH(1,Calc!$J$43:$J$46,0)),0) -> 2 | AE31: =IFERROR(INDEX(Calc!$G$43:$G$46,MATCH(1,Calc!$J$43:$J$46,0)),0) -> 6 | AF31: =IFERROR(ROUND(INDEX(Calc!$H$43:$H$46,MATCH(1,Calc!$J$43:$J$46,0))/(INDEX(Calc!$K$43:$K$46,MATCH(1,Calc!$J$43:$J$46,0))*3)*100,0),0) -> 78 | AG31: 1 | AH31: =IFERROR(INDEX(Calc!$B$47:$B$50,MATCH(1,Calc!$J$47:$J$50,0)),"?") -> Inglaterra | AN31: =IFERROR(INDEX(Calc!$H$47:$H$50,MATCH(1,Calc!$J$47:$J$50,0)),0) -> 9 | AO31: =IFERROR(INDEX(Calc!$K$47:$K$50,MATCH(1,Calc!$J$47:$J$50,0)),0) -> 3 | AP31: =IFERROR(INDEX(Calc!$C$47:$C$50,MATCH(1,Calc!$J$47:$J$50,0)),0) -> 3 | AQ31: =IFERROR(INDEX(Calc!$D$47:$D$50,MATCH(1,Calc!$J$47:$J$50,0)),0) -> 0 | AR31: =IFERROR(INDEX(Calc!$L$47:$L$50,MATCH(1,Calc!$J$47:$J$50,0)),0) -> 0 | AS31: =IFERROR(INDEX(Calc!$E$47:$E$50,MATCH(1,Calc!$J$47:$J$50,0)),0) -> 8 | AT31: =IFERROR(INDEX(Calc!$F$47:$F$50,MATCH(1,Calc!$J$47:$J$50,0)),0) -> 2 | AU31: =IFERROR(INDEX(Calc!$G$47:$G$50,MATCH(1,Calc!$J$47:$J$50,0)),0) -> 6 | AV31: =IFERROR(ROUND(INDEX(Calc!$H$47:$H$50,MATCH(1,Calc!$J$47:$J$50,0))/(INDEX(Calc!$K$47:$K$50,MATCH(1,Calc!$J$47:$J$50,0))*3)*100,0),0) -> 100
A32: 2 | B32: =IFERROR(INDEX(Calc!$B$39:$B$42,MATCH(2,Calc!$J$39:$J$42,0)),"?") -> Argelia | H32: =IFERROR(INDEX(Calc!$H$39:$H$42,MATCH(2,Calc!$J$39:$J$42,0)),0) -> 4 | I32: =IFERROR(INDEX(Calc!$K$39:$K$42,MATCH(2,Calc!$J$39:$J$42,0)),0) -> 3 | J32: =IFERROR(INDEX(Calc!$C$39:$C$42,MATCH(2,Calc!$J$39:$J$42,0)),0) -> 1 | K32: =IFERROR(INDEX(Calc!$D$39:$D$42,MATCH(2,Calc!$J$39:$J$42,0)),0) -> 1 | L32: =IFERROR(INDEX(Calc!$L$39:$L$42,MATCH(2,Calc!$J$39:$J$42,0)),0) -> 1 | M32: =IFERROR(INDEX(Calc!$E$39:$E$42,MATCH(2,Calc!$J$39:$J$42,0)),0) -> 4 | N32: =IFERROR(INDEX(Calc!$F$39:$F$42,MATCH(2,Calc!$J$39:$J$42,0)),0) -> 4 | O32: =IFERROR(INDEX(Calc!$G$39:$G$42,MATCH(2,Calc!$J$39:$J$42,0)),0) -> 0 | P32: =IFERROR(ROUND(INDEX(Calc!$H$39:$H$42,MATCH(2,Calc!$J$39:$J$42,0))/(INDEX(Calc!$K$39:$K$42,MATCH(2,Calc!$J$39:$J$42,0))*3)*100,0),0) -> 44 | Q32: 2 | R32: =IFERROR(INDEX(Calc!$B$43:$B$46,MATCH(2,Calc!$J$43:$J$46,0)),"?") -> Colombia | X32: =IFERROR(INDEX(Calc!$H$43:$H$46,MATCH(2,Calc!$J$43:$J$46,0)),0) -> 7 | Y32: =IFERROR(INDEX(Calc!$K$43:$K$46,MATCH(2,Calc!$J$43:$J$46,0)),0) -> 3 | Z32: =IFERROR(INDEX(Calc!$C$43:$C$46,MATCH(2,Calc!$J$43:$J$46,0)),0) -> 2 | AA32: =IFERROR(INDEX(Calc!$D$43:$D$46,MATCH(2,Calc!$J$43:$J$46,0)),0) -> 1 | AB32: =IFERROR(INDEX(Calc!$L$43:$L$46,MATCH(2,Calc!$J$43:$J$46,0)),0) -> 0 | AC32: =IFERROR(INDEX(Calc!$E$43:$E$46,MATCH(2,Calc!$J$43:$J$46,0)),0) -> 6 | AD32: =IFERROR(INDEX(Calc!$F$43:$F$46,MATCH(2,Calc!$J$43:$J$46,0)),0) -> 2 | AE32: =IFERROR(INDEX(Calc!$G$43:$G$46,MATCH(2,Calc!$J$43:$J$46,0)),0) -> 4 | AF32: =IFERROR(ROUND(INDEX(Calc!$H$43:$H$46,MATCH(2,Calc!$J$43:$J$46,0))/(INDEX(Calc!$K$43:$K$46,MATCH(2,Calc!$J$43:$J$46,0))*3)*100,0),0) -> 78 | AG32: 2 | AH32: =IFERROR(INDEX(Calc!$B$47:$B$50,MATCH(2,Calc!$J$47:$J$50,0)),"?") -> Croacia | AN32: =IFERROR(INDEX(Calc!$H$47:$H$50,MATCH(2,Calc!$J$47:$J$50,0)),0) -> 4 | AO32: =IFERROR(INDEX(Calc!$K$47:$K$50,MATCH(2,Calc!$J$47:$J$50,0)),0) -> 3 | AP32: =IFERROR(INDEX(Calc!$C$47:$C$50,MATCH(2,Calc!$J$47:$J$50,0)),0) -> 1 | AQ32: =IFERROR(INDEX(Calc!$D$47:$D$50,MATCH(2,Calc!$J$47:$J$50,0)),0) -> 1 | AR32: =IFERROR(INDEX(Calc!$L$47:$L$50,MATCH(2,Calc!$J$47:$J$50,0)),0) -> 1 | AS32: =IFERROR(INDEX(Calc!$E$47:$E$50,MATCH(2,Calc!$J$47:$J$50,0)),0) -> 5 | AT32: =IFERROR(INDEX(Calc!$F$47:$F$50,MATCH(2,Calc!$J$47:$J$50,0)),0) -> 4 | AU32: =IFERROR(INDEX(Calc!$G$47:$G$50,MATCH(2,Calc!$J$47:$J$50,0)),0) -> 1 | AV32: =IFERROR(ROUND(INDEX(Calc!$H$47:$H$50,MATCH(2,Calc!$J$47:$J$50,0))/(INDEX(Calc!$K$47:$K$50,MATCH(2,Calc!$J$47:$J$50,0))*3)*100,0),0) -> 44
A33: 3 | B33: =IFERROR(INDEX(Calc!$B$39:$B$42,MATCH(3,Calc!$J$39:$J$42,0)),"?") -> Austria | H33: =IFERROR(INDEX(Calc!$H$39:$H$42,MATCH(3,Calc!$J$39:$J$42,0)),0) -> 4 | I33: =IFERROR(INDEX(Calc!$K$39:$K$42,MATCH(3,Calc!$J$39:$J$42,0)),0) -> 3 | J33: =IFERROR(INDEX(Calc!$C$39:$C$42,MATCH(3,Calc!$J$39:$J$42,0)),0) -> 1 | K33: =IFERROR(INDEX(Calc!$D$39:$D$42,MATCH(3,Calc!$J$39:$J$42,0)),0) -> 1 | L33: =IFERROR(INDEX(Calc!$L$39:$L$42,MATCH(3,Calc!$J$39:$J$42,0)),0) -> 1 | M33: =IFERROR(INDEX(Calc!$E$39:$E$42,MATCH(3,Calc!$J$39:$J$42,0)),0) -> 2 | N33: =IFERROR(INDEX(Calc!$F$39:$F$42,MATCH(3,Calc!$J$39:$J$42,0)),0) -> 3 | O33: =IFERROR(INDEX(Calc!$G$39:$G$42,MATCH(3,Calc!$J$39:$J$42,0)),0) -> -1 | P33: =IFERROR(ROUND(INDEX(Calc!$H$39:$H$42,MATCH(3,Calc!$J$39:$J$42,0))/(INDEX(Calc!$K$39:$K$42,MATCH(3,Calc!$J$39:$J$42,0))*3)*100,0),0) -> 44 | Q33: 3 | R33: =IFERROR(INDEX(Calc!$B$43:$B$46,MATCH(3,Calc!$J$43:$J$46,0)),"?") -> RD Congo | X33: =IFERROR(INDEX(Calc!$H$43:$H$46,MATCH(3,Calc!$J$43:$J$46,0)),0) -> 1 | Y33: =IFERROR(INDEX(Calc!$K$43:$K$46,MATCH(3,Calc!$J$43:$J$46,0)),0) -> 3 | Z33: =IFERROR(INDEX(Calc!$C$43:$C$46,MATCH(3,Calc!$J$43:$J$46,0)),0) -> 0 | AA33: =IFERROR(INDEX(Calc!$D$43:$D$46,MATCH(3,Calc!$J$43:$J$46,0)),0) -> 1 | AB33: =IFERROR(INDEX(Calc!$L$43:$L$46,MATCH(3,Calc!$J$43:$J$46,0)),0) -> 2 | AC33: =IFERROR(INDEX(Calc!$E$43:$E$46,MATCH(3,Calc!$J$43:$J$46,0)),0) -> 0 | AD33: =IFERROR(INDEX(Calc!$F$43:$F$46,MATCH(3,Calc!$J$43:$J$46,0)),0) -> 5 | AE33: =IFERROR(INDEX(Calc!$G$43:$G$46,MATCH(3,Calc!$J$43:$J$46,0)),0) -> -5 | AF33: =IFERROR(ROUND(INDEX(Calc!$H$43:$H$46,MATCH(3,Calc!$J$43:$J$46,0))/(INDEX(Calc!$K$43:$K$46,MATCH(3,Calc!$J$43:$J$46,0))*3)*100,0),0) -> 11 | AG33: 3 | AH33: =IFERROR(INDEX(Calc!$B$47:$B$50,MATCH(3,Calc!$J$47:$J$50,0)),"?") -> Gana | AN33: =IFERROR(INDEX(Calc!$H$47:$H$50,MATCH(3,Calc!$J$47:$J$50,0)),0) -> 4 | AO33: =IFERROR(INDEX(Calc!$K$47:$K$50,MATCH(3,Calc!$J$47:$J$50,0)),0) -> 3 | AP33: =IFERROR(INDEX(Calc!$C$47:$C$50,MATCH(3,Calc!$J$47:$J$50,0)),0) -> 1 | AQ33: =IFERROR(INDEX(Calc!$D$47:$D$50,MATCH(3,Calc!$J$47:$J$50,0)),0) -> 1 | AR33: =IFERROR(INDEX(Calc!$L$47:$L$50,MATCH(3,Calc!$J$47:$J$50,0)),0) -> 1 | AS33: =IFERROR(INDEX(Calc!$E$47:$E$50,MATCH(3,Calc!$J$47:$J$50,0)),0) -> 6 | AT33: =IFERROR(INDEX(Calc!$F$47:$F$50,MATCH(3,Calc!$J$47:$J$50,0)),0) -> 6 | AU33: =IFERROR(INDEX(Calc!$G$47:$G$50,MATCH(3,Calc!$J$47:$J$50,0)),0) -> 0 | AV33: =IFERROR(ROUND(INDEX(Calc!$H$47:$H$50,MATCH(3,Calc!$J$47:$J$50,0))/(INDEX(Calc!$K$47:$K$50,MATCH(3,Calc!$J$47:$J$50,0))*3)*100,0),0) -> 44
A34: 4 | B34: =IFERROR(INDEX(Calc!$B$39:$B$42,MATCH(4,Calc!$J$39:$J$42,0)),"?") -> Jordania | H34: =IFERROR(INDEX(Calc!$H$39:$H$42,MATCH(4,Calc!$J$39:$J$42,0)),0) -> 0 | I34: =IFERROR(INDEX(Calc!$K$39:$K$42,MATCH(4,Calc!$J$39:$J$42,0)),0) -> 3 | J34: =IFERROR(INDEX(Calc!$C$39:$C$42,MATCH(4,Calc!$J$39:$J$42,0)),0) -> 0 | K34: =IFERROR(INDEX(Calc!$D$39:$D$42,MATCH(4,Calc!$J$39:$J$42,0)),0) -> 0 | L34: =IFERROR(INDEX(Calc!$L$39:$L$42,MATCH(4,Calc!$J$39:$J$42,0)),0) -> 3 | M34: =IFERROR(INDEX(Calc!$E$39:$E$42,MATCH(4,Calc!$J$39:$J$42,0)),0) -> 1 | N34: =IFERROR(INDEX(Calc!$F$39:$F$42,MATCH(4,Calc!$J$39:$J$42,0)),0) -> 7 | O34: =IFERROR(INDEX(Calc!$G$39:$G$42,MATCH(4,Calc!$J$39:$J$42,0)),0) -> -6 | P34: =IFERROR(ROUND(INDEX(Calc!$H$39:$H$42,MATCH(4,Calc!$J$39:$J$42,0))/(INDEX(Calc!$K$39:$K$42,MATCH(4,Calc!$J$39:$J$42,0))*3)*100,0),0) -> 0 | Q34: 4 | R34: =IFERROR(INDEX(Calc!$B$43:$B$46,MATCH(4,Calc!$J$43:$J$46,0)),"?") -> Uzbequistao | X34: =IFERROR(INDEX(Calc!$H$43:$H$46,MATCH(4,Calc!$J$43:$J$46,0)),0) -> 1 | Y34: =IFERROR(INDEX(Calc!$K$43:$K$46,MATCH(4,Calc!$J$43:$J$46,0)),0) -> 3 | Z34: =IFERROR(INDEX(Calc!$C$43:$C$46,MATCH(4,Calc!$J$43:$J$46,0)),0) -> 0 | AA34: =IFERROR(INDEX(Calc!$D$43:$D$46,MATCH(4,Calc!$J$43:$J$46,0)),0) -> 1 | AB34: =IFERROR(INDEX(Calc!$L$43:$L$46,MATCH(4,Calc!$J$43:$J$46,0)),0) -> 2 | AC34: =IFERROR(INDEX(Calc!$E$43:$E$46,MATCH(4,Calc!$J$43:$J$46,0)),0) -> 0 | AD34: =IFERROR(INDEX(Calc!$F$43:$F$46,MATCH(4,Calc!$J$43:$J$46,0)),0) -> 5 | AE34: =IFERROR(INDEX(Calc!$G$43:$G$46,MATCH(4,Calc!$J$43:$J$46,0)),0) -> -5 | AF34: =IFERROR(ROUND(INDEX(Calc!$H$43:$H$46,MATCH(4,Calc!$J$43:$J$46,0))/(INDEX(Calc!$K$43:$K$46,MATCH(4,Calc!$J$43:$J$46,0))*3)*100,0),0) -> 11 | AG34: 4 | AH34: =IFERROR(INDEX(Calc!$B$47:$B$50,MATCH(4,Calc!$J$47:$J$50,0)),"?") -> Panama | AN34: =IFERROR(INDEX(Calc!$H$47:$H$50,MATCH(4,Calc!$J$47:$J$50,0)),0) -> 0 | AO34: =IFERROR(INDEX(Calc!$K$47:$K$50,MATCH(4,Calc!$J$47:$J$50,0)),0) -> 3 | AP34: =IFERROR(INDEX(Calc!$C$47:$C$50,MATCH(4,Calc!$J$47:$J$50,0)),0) -> 0 | AQ34: =IFERROR(INDEX(Calc!$D$47:$D$50,MATCH(4,Calc!$J$47:$J$50,0)),0) -> 0 | AR34: =IFERROR(INDEX(Calc!$L$47:$L$50,MATCH(4,Calc!$J$47:$J$50,0)),0) -> 3 | AS34: =IFERROR(INDEX(Calc!$E$47:$E$50,MATCH(4,Calc!$J$47:$J$50,0)),0) -> 1 | AT34: =IFERROR(INDEX(Calc!$F$47:$F$50,MATCH(4,Calc!$J$47:$J$50,0)),0) -> 8 | AU34: =IFERROR(INDEX(Calc!$G$47:$G$50,MATCH(4,Calc!$J$47:$J$50,0)),0) -> -7 | AV34: =IFERROR(ROUND(INDEX(Calc!$H$47:$H$50,MATCH(4,Calc!$J$47:$J$50,0))/(INDEX(Calc!$K$47:$K$50,MATCH(4,Calc!$J$47:$J$50,0))*3)*100,0),0) -> 0

Sheet Jogadores
A1: Seleção | B1: Jogador | D1: Seleções
A2: Arábia Saudita | B2: Mohammed Al-Owais | D2: Mexico
A3: Arábia Saudita | B3: Nawaf Al-Aqidi | D3: Africa do Sul
A4: Arábia Saudita | B4: Ahmed Al-Kassar | D4: Coreia do Sul
A5: Arábia Saudita | B5: Ali Al-Bulayhi | D5: Tchequia
A6: Arábia Saudita | B6: Hassan Kadesh | D6: Canada
A7: Arábia Saudita | B7: Yasir Al-Shahrani | D7: Bosnia e Herzegovina
A8: Arábia Saudita | B8: Nawaf Boushal | D8: Qatar
A9: Arábia Saudita | B9: Sultan Al-Ghannam | D9: Suica
A10: Arábia Saudita | B10: Nasser Al-Dawsari | D10: Brasil
A11: Arábia Saudita | B11: Musab Al-Juwayr | D11: Marrocos
A12: Arábia Saudita | B12: Faisal Al-Ghamdi | D12: Haiti
... A49: Iraque | B49: Hussein Ali | D49: Panama
A50: Iraque | B50: Zaid Tahseen
A51: Iraque | B51: Ali Jasim
A52: Iraque | B52: Ibrahim Bayesh
A53: Iraque | B53: Zidane Iqbal
A54: Iraque | B54: Amir Al-Ammari
A55: Iraque | B55: Osama Rashid
A56: Iraque | B56: Youssef Amyn
A57: Iraque | B57: Mohanad Ali
A58: Iraque | B58: Aymen Hussein
A59: Iraque | B59: Ali Al-Hamadi
A60: Iraque | B60: Marko Farji
A61: Iraque | B61: Peter Gwargis
... A817: Turquia | B817: İsmail Yüksek

Sheet Calc
A1: CALC - CLASSIFICACAO DO APOSTADOR (Auxiliar nao editar)
A3: A | B3: Mexico | C3: =IF(AND(ISNUMBER('Apostas - Grupos'!B5),ISNUMBER('Apostas - Grupos'!C5)),IF('Apostas - Grupos'!B5>'Apostas - Grupos'!C5,1,0),0)+IF(AND(ISNUMBER('Apostas - Grupos'!H5),ISNUMBER('Apostas - Grupos'!I5)),IF('Apostas - Grupos'!H5>'Apostas - Grupos'!I5,1,0),0)+IF(AND(ISNUMBER('Apostas - Grupos'!J5),ISNUMBER('Apostas - Grupos'!K5)),IF('Apostas - Grupos'!K5>'Apostas - Grupos'!J5,1,0),0) -> 2 | D3: =IF(AND(ISNUMBER('Apostas - Grupos'!B5),ISNUMBER('Apostas - Grupos'!C5)),IF('Apostas - Grupos'!B5='Apostas - Grupos'!C5,1,0),0)+IF(AND(ISNUMBER('Apostas - Grupos'!H5),ISNUMBER('Apostas - Grupos'!I5)),IF('Apostas - Grupos'!H5='Apostas - Grupos'!I5,1,0),0)+IF(AND(ISNUMBER('Apostas - Grupos'!J5),ISNUMBER('Apostas - Grupos'!K5)),IF('Apostas - Grupos'!J5='Apostas - Grupos'!K5,1,0),0) -> 1 | E3: =IF(ISNUMBER('Apostas - Grupos'!B5),'Apostas - Grupos'!B5,0)+IF(ISNUMBER('Apostas - Grupos'!H5),'Apostas - Grupos'!H5,0)+IF(ISNUMBER('Apostas - Grupos'!J5),'Apostas - Grupos'!K5,0) -> 5 | F3: =IF(ISNUMBER('Apostas - Grupos'!B5),'Apostas - Grupos'!C5,0)+IF(ISNUMBER('Apostas - Grupos'!H5),'Apostas - Grupos'!I5,0)+IF(ISNUMBER('Apostas - Grupos'!J5),'Apostas - Grupos'!J5,0) -> 2 | G3: =E3-F3 -> 3 | H3: =3*C3+D3 -> 7 | I3: =H3*1000000000+(G3+200)*1000000+E3*1000+(500-M3) -> 7203005484 | J3: =RANK(I3,$I$3:$I$6,0) -> 1 | K3: =IF(AND(ISNUMBER('Apostas - Grupos'!B5),ISNUMBER('Apostas - Grupos'!C5)),1,0)+IF(AND(ISNUMBER('Apostas - Grupos'!H5),ISNUMBER('Apostas - Grupos'!I5)),1,0)+IF(AND(ISNUMBER('Apostas - Grupos'!J5),ISNUMBER('Apostas - Grupos'!K5)),1,0) -> 3 | L3: =K3-C3-D3 -> 0 | M3: 16
A4: A | B4: Africa do Sul | C4: =IF(AND(ISNUMBER('Apostas - Grupos'!B5),ISNUMBER('Apostas - Grupos'!C5)),IF('Apostas - Grupos'!C5>'Apostas - Grupos'!B5,1,0),0)+IF(AND(ISNUMBER('Apostas - Grupos'!F5),ISNUMBER('Apostas - Grupos'!G5)),IF('Apostas - Grupos'!G5>'Apostas - Grupos'!F5,1,0),0)+IF(AND(ISNUMBER('Apostas - Grupos'!L5),ISNUMBER('Apostas - Grupos'!M5)),IF('Apostas - Grupos'!L5>'Apostas - Grupos'!M5,1,0),0) -> 0 | D4: =IF(AND(ISNUMBER('Apostas - Grupos'!B5),ISNUMBER('Apostas - Grupos'!C5)),IF('Apostas - Grupos'!B5='Apostas - Grupos'!C5,1,0),0)+IF(AND(ISNUMBER('Apostas - Grupos'!F5),ISNUMBER('Apostas - Grupos'!G5)),IF('Apostas - Grupos'!F5='Apostas - Grupos'!G5,1,0),0)+IF(AND(ISNUMBER('Apostas - Grupos'!L5),ISNUMBER('Apostas - Grupos'!M5)),IF('Apostas - Grupos'!L5='Apostas - Grupos'!M5,1,0),0) -> 0 | E4: =IF(ISNUMBER('Apostas - Grupos'!B5),'Apostas - Grupos'!C5,0)+IF(ISNUMBER('Apostas - Grupos'!F5),'Apostas - Grupos'!G5,0)+IF(ISNUMBER('Apostas - Grupos'!L5),'Apostas - Grupos'!L5,0) -> 2 | F4: =IF(ISNUMBER('Apostas - Grupos'!B5),'Apostas - Grupos'!B5,0)+IF(ISNUMBER('Apostas - Grupos'!F5),'Apostas - Grupos'!F5,0)+IF(ISNUMBER('Apostas - Grupos'!L5),'Apostas - Grupos'!M5,0) -> 7 | G4: =E4-F4 -> -5 | H4: =3*C4+D4 -> 0 | I4: =H4*1000000000+(G4+200)*1000000+E4*1000+(500-M4) -> 195002437 | J4: =RANK(I4,$I$3:$I$6,0) -> 4 | K4: =IF(AND(ISNUMBER('Apostas - Grupos'!B5),ISNUMBER('Apostas - Grupos'!C5)),1,0)+IF(AND(ISNUMBER('Apostas - Grupos'!F5),ISNUMBER('Apostas - Grupos'!G5)),1,0)+IF(AND(ISNUMBER('Apostas - Grupos'!L5),ISNUMBER('Apostas - Grupos'!M5)),1,0) -> 3 | L4: =K4-C4-D4 -> 3 | M4: 63
A5: A | B5: Coreia do Sul | C5: =IF(AND(ISNUMBER('Apostas - Grupos'!D5),ISNUMBER('Apostas - Grupos'!E5)),IF('Apostas - Grupos'!D5>'Apostas - Grupos'!E5,1,0),0)+IF(AND(ISNUMBER('Apostas - Grupos'!H5),ISNUMBER('Apostas - Grupos'!I5)),IF('Apostas - Grupos'!I5>'Apostas - Grupos'!H5,1,0),0)+IF(AND(ISNUMBER('Apostas - Grupos'!L5),ISNUMBER('Apostas - Grupos'!M5)),IF('Apostas - Grupos'!M5>'Apostas - Grupos'!L5,1,0),0) -> 1 | D5: =IF(AND(ISNUMBER('Apostas - Grupos'!D5),ISNUMBER('Apostas - Grupos'!E5)),IF('Apostas - Grupos'!D5='Apostas - Grupos'!E5,1,0),0)+IF(AND(ISNUMBER('Apostas - Grupos'!H5),ISNUMBER('Apostas - Grupos'!I5)),IF('Apostas - Grupos'!H5='Apostas - Grupos'!I5,1,0),0)+IF(AND(ISNUMBER('Apostas - Grupos'!L5),ISNUMBER('Apostas - Grupos'!M5)),IF('Apostas - Grupos'!L5='Apostas - Grupos'!M5,1,0),0) -> 1 | E5: =IF(ISNUMBER('Apostas - Grupos'!D5),'Apostas - Grupos'!D5,0)+IF(ISNUMBER('Apostas - Grupos'!H5),'Apostas - Grupos'!I5,0)+IF(ISNUMBER('Apostas - Grupos'!L5),'Apostas - Grupos'!M5,0) -> 4 | F5: =IF(ISNUMBER('Apostas - Grupos'!D5),'Apostas - Grupos'!E5,0)+IF(ISNUMBER('Apostas - Grupos'!H5),'Apostas - Grupos'!H5,0)+IF(ISNUMBER('Apostas - Grupos'!L5),'Apostas - Grupos'!L5,0) -> 4 | G5: =E5-F5 -> 0 | H5: =3*C5+D5 -> 4 | I5: =H5*1000000000+(G5+200)*1000000+E5*1000+(500-M5) -> 4200004477 | J5: =RANK(I5,$I$3:$I$6,0) -> 3 | K5: =IF(AND(ISNUMBER('Apostas - Grupos'!D5),ISNUMBER('Apostas - Grupos'!E5)),1,0)+IF(AND(ISNUMBER('Apostas - Grupos'!H5),ISNUMBER('Apostas - Grupos'!I5)),1,0)+IF(AND(ISNUMBER('Apostas - Grupos'!L5),ISNUMBER('Apostas - Grupos'!M5)),1,0) -> 3 | L5: =K5-C5-D5 -> 1 | M5: 23
A6: A | B6: Tchequia | C6: =IF(AND(ISNUMBER('Apostas - Grupos'!D5),ISNUMBER('Apostas - Grupos'!E5)),IF('Apostas - Grupos'!E5>'Apostas - Grupos'!D5,1,0),0)+IF(AND(ISNUMBER('Apostas - Grupos'!F5),ISNUMBER('Apostas - Grupos'!G5)),IF('Apostas - Grupos'!F5>'Apostas - Grupos'!G5,1,0),0)+IF(AND(ISNUMBER('Apostas - Grupos'!J5),ISNUMBER('Apostas - Grupos'!K5)),IF('Apostas - Grupos'!J5>'Apostas - Grupos'!K5,1,0),0) -> 1 | D6: =IF(AND(ISNUMBER('Apostas - Grupos'!D5),ISNUMBER('Apostas - Grupos'!E5)),IF('Apostas - Grupos'!D5='Apostas - Grupos'!E5,1,0),0)+IF(AND(ISNUMBER('Apostas - Grupos'!F5),ISNUMBER('Apostas - Grupos'!G5)),IF('Apostas - Grupos'!F5='Apostas - Grupos'!G5,1,0),0)+IF(AND(ISNUMBER('Apostas - Grupos'!J5),ISNUMBER('Apostas - Grupos'!K5)),IF('Apostas - Grupos'!J5='Apostas - Grupos'!K5,1,0),0) -> 2 | E6: =IF(ISNUMBER('Apostas - Grupos'!D5),'Apostas - Grupos'!E5,0)+IF(ISNUMBER('Apostas - Grupos'!F5),'Apostas - Grupos'!F5,0)+IF(ISNUMBER('Apostas - Grupos'!J5),'Apostas - Grupos'!J5,0) -> 5 | F6: =IF(ISNUMBER('Apostas - Grupos'!D5),'Apostas - Grupos'!D5,0)+IF(ISNUMBER('Apostas - Grupos'!F5),'Apostas - Grupos'!G5,0)+IF(ISNUMBER('Apostas - Grupos'!J5),'Apostas - Grupos'!K5,0) -> 3 | G6: =E6-F6 -> 2 | H6: =3*C6+D6 -> 5 | I6: =H6*1000000000+(G6+200)*1000000+E6*1000+(500-M6) -> 5202005462 | J6: =RANK(I6,$I$3:$I$6,0) -> 2 | K6: =IF(AND(ISNUMBER('Apostas - Grupos'!D5),ISNUMBER('Apostas - Grupos'!E5)),1,0)+IF(AND(ISNUMBER('Apostas - Grupos'!F5),ISNUMBER('Apostas - Grupos'!G5)),1,0)+IF(AND(ISNUMBER('Apostas - Grupos'!J5),ISNUMBER('Apostas - Grupos'!K5)),1,0) -> 3 | L6: =K6-C6-D6 -> 0 | M6: 38
A7: B | B7: Canada | C7: =IF(AND(ISNUMBER('Apostas - Grupos'!N5),ISNUMBER('Apostas - Grupos'!O5)),IF('Apostas - Grupos'!N5>'Apostas - Grupos'!O5,1,0),0)+IF(AND(ISNUMBER('Apostas - Grupos'!T5),ISNUMBER('Apostas - Grupos'!U5)),IF('Apostas - Grupos'!T5>'Apostas - Grupos'!U5,1,0),0)+IF(AND(ISNUMBER('Apostas - Grupos'!V5),ISNUMBER('Apostas - Grupos'!W5)),IF('Apostas - Grupos'!W5>'Apostas - Grupos'!V5,1,0),0) -> 1 | D7: =IF(AND(ISNUMBER('Apostas - Grupos'!N5),ISNUMBER('Apostas - Grupos'!O5)),IF('Apostas - Grupos'!N5='Apostas - Grupos'!O5,1,0),0)+IF(AND(ISNUMBER('Apostas - Grupos'!T5),ISNUMBER('Apostas - Grupos'!U5)),IF('Apostas - Grupos'!T5='Apostas - Grupos'!U5,1,0),0)+IF(AND(ISNUMBER('Apostas - Grupos'!V5),ISNUMBER('Apostas - Grupos'!W5)),IF('Apostas - Grupos'!V5='Apostas - Grupos'!W5,1,0),0) -> 2 | E7: =IF(ISNUMBER('Apostas - Grupos'!N5),'Apostas - Grupos'!N5,0)+IF(ISNUMBER('Apostas - Grupos'!T5),'Apostas - Grupos'!T5,0)+IF(ISNUMBER('Apostas - Grupos'!V5),'Apostas - Grupos'!W5,0) -> 4 | F7: =IF(ISNUMBER('Apostas - Grupos'!N5),'Apostas - Grupos'!O5,0)+IF(ISNUMBER('Apostas - Grupos'!T5),'Apostas - Grupos'!U5,0)+IF(ISNUMBER('Apostas - Grupos'!V5),'Apostas - Grupos'!V5,0) -> 2 | G7: =E7-F7 -> 2 | H7: =3*C7+D7 -> 5 | I7: =H7*1000000000+(G7+200)*1000000+E7*1000+(500-M7) -> 5202004456 | J7: =RANK(I7,$I$7:$I$10,0) -> 2 | K7: =IF(AND(ISNUMBER('Apostas - Grupos'!N5),ISNUMBER('Apostas - Grupos'!O5)),1,0)+IF(AND(ISNUMBER('Apostas - Grupos'!T5),ISNUMBER('Apostas - Grupos'!U5)),1,0)+IF(AND(ISNUMBER('Apostas - Grupos'!V5),ISNUMBER('Apostas - Grupos'!W5)),1,0) -> 3 | L7: =K7-C7-D7 -> 0 | M7: 44
A8: B | B8: Bosnia e Herzegovina | C8: =IF(AND(ISNUMBER('Apostas - Grupos'!N5),ISNUMBER('Apostas - Grupos'!O5)),IF('Apostas - Grupos'!O5>'Apostas - Grupos'!N5,1,0),0)+IF(AND(ISNUMBER('Apostas - Grupos'!R5),ISNUMBER('Apostas - Grupos'!S5)),IF('Apostas - Grupos'!S5>'Apostas - Grupos'!R5,1,0),0)+IF(AND(ISNUMBER('Apostas - Grupos'!X5),ISNUMBER('Apostas - Grupos'!Y5)),IF('Apostas - Grupos'!X5>'Apostas - Grupos'!Y5,1,0),0) -> 0 | D8: =IF(AND(ISNUMBER('Apostas - Grupos'!N5),ISNUMBER('Apostas - Grupos'!O5)),IF('Apostas - Grupos'!N5='Apostas - Grupos'!O5,1,0),0)+IF(AND(ISNUMBER('Apostas - Grupos'!R5),ISNUMBER('Apostas - Grupos'!S5)),IF('Apostas - Grupos'!R5='Apostas - Grupos'!S5,1,0),0)+IF(AND(ISNUMBER('Apostas - Grupos'!X5),ISNUMBER('Apostas - Grupos'!Y5)),IF('Apostas - Grupos'!X5='Apostas - Grupos'!Y5,1,0),0) -> 2 | E8: =IF(ISNUMBER('Apostas - Grupos'!N5),'Apostas - Grupos'!O5,0)+IF(ISNUMBER('Apostas - Grupos'!R5),'Apostas - Grupos'!S5,0)+IF(ISNUMBER('Apostas - Grupos'!X5),'Apostas - Grupos'!X5,0) -> 4 | F8: =IF(ISNUMBER('Apostas - Grupos'!N5),'Apostas - Grupos'!N5,0)+IF(ISNUMBER('Apostas - Grupos'!R5),'Apostas - Grupos'!R5,0)+IF(ISNUMBER('Apostas - Grupos'!X5),'Apostas - Grupos'!Y5,0) -> 6 | G8: =E8-F8 -> -2 | H8: =3*C8+D8 -> 2 | I8: =H8*1000000000+(G8+200)*1000000+E8*1000+(500-M8) -> 2198004445 | J8: =RANK(I8,$I$7:$I$10,0) -> 3 | K8: =IF(AND(ISNUMBER('Apostas - Grupos'!N5),ISNUMBER('Apostas - Grupos'!O5)),1,0)+IF(AND(ISNUMBER('Apostas - Grupos'!R5),ISNUMBER('Apostas - Grupos'!S5)),1,0)+IF(AND(ISNUMBER('Apostas - Grupos'!X5),ISNUMBER('Apostas - Grupos'!Y5)),1,0) -> 3 | L8: =K8-C8-D8 -> 1 | M8: 55
