Workbook

Sheet Regras
B1: BOLAO COPA DO MUNDO 2026 - TURIM MFO
B2: REGULAMENTO OFICIAL v7 - ENVIO UNICO | BRACKET FIFA CORRETO
B3: COMO FUNCIONA
B4: Envio UNICO antes da Copa. Preencha tudo de uma vez: grupos, bonus e mata-mata.
B5: Os confrontos do mata-mata sao calculados automaticamente com base nos seus palpites dos grupos.
B6: O bracket segue o formato oficial da FIFA (M73-M88) com a tabela de 495 combinacoes de 3os colocados.
B8: APOSTAS - GRUPOS (max 360 pts)
B9: Placar Exato (ex: 2x1 apostado, 2x1 real) | C9: 5 pontos
B10: Resultado Correto + Saldo Correto (2x0 apostado, 3x1 real) | C10: 3 pontos
B11: Apenas Resultado Correto (1x0 apostado, 3x2 real) | C11: 2 pontos
B12: Resultado Errado | C12: 0 pontos
B14: APOSTAS - BONUS (max 15 pts)
B15: Artilheiro correto | C15: 10 pontos
B16: Selecao com melhor campanha na fase de grupos | C16: 5 pontos
B18: APOSTAS - MATA-MATA (coloque X no time que avanca)
B19: Para cada jogo eliminatorio, coloque X no time que voce acredita que vai avançar. | C19: Celulas laranjas
B20: Os confrontos da Rodada de 32 sao definidos automaticamente pelos seus palpites dos grupos.
B21: A Rodada de 32 segue o bracket oficial da FIFA (M73-M88), incluindo a tabela de 495 combinacoes de 3os colocados.
B22: Preencha da esquerda para a direita: R32 primeiro, depois Oitavas, Quartas, Semis e Final.
B24: PONTUACAO - MATA-MATA (peso cresce por fase)
B25: Rodada de 32 (M73-M88) | C25: 3 pontos por acerto
B26: Oitavas de Final | C26: 5 pontos por acerto
B27: Quartas de Final | C27: 8 pontos por acerto
B28: Semifinais | C28: 12 pontos por acerto
B29: 3o Lugar | C29: 10 pontos por acerto
B30: Final (Campeao) | C30: 25 pontos
B32: CRITERIOS DE DESEMPATE
B33: 1o) Maior pontuacao no Mata-Mata.
B34: 2o) Maior numero de acertos de 5 pts na fase de grupos.
B35: 3o) Maior pontuacao na fase de grupos.
B36: 4o) Sorteio.
B38: Administrador: ___________________________ | Versao 6.0 - Copa 2026

Sheet Jogos - Grupos
A1: COPA DO MUNDO 2026 - CALENDARIO: FASE DE GRUPOS
A2: ID | B2: Data | C2: Grupo | D2: Selecao 1 | E2: Selecao 2 | F2: Gols S1 | G2: Gols S2 | H2: Status
A3: G001 | B3: 46184 | C3: A | D3: Mexico | E3: Africa do Sul | F3: 2 | G3: 0 | H3: =IF(AND(F3="",G3=""),"Aguardando",IF(AND(ISNUMBER(F3),ISNUMBER(G3)),"Finalizado","Verificar")) -> Finalizado
A4: G002 | B4: 46184 | C4: A | D4: Coreia do Sul | E4: Tchequia | F4: 2 | G4: 1 | H4: =IF(AND(F4="",G4=""),"Aguardando",IF(AND(ISNUMBER(F4),ISNUMBER(G4)),"Finalizado","Verificar")) -> Finalizado
A5: G003 | B5: 46191 | C5: A | D5: Tchequia | E5: Africa do Sul | H5: =IF(AND(F5="",G5=""),"Aguardando",IF(AND(ISNUMBER(F5),ISNUMBER(G5)),"Finalizado","Verificar")) -> Aguardando
A6: G004 | B6: 46191 | C6: A | D6: Mexico | E6: Coreia do Sul | H6: =IF(AND(F6="",G6=""),"Aguardando",IF(AND(ISNUMBER(F6),ISNUMBER(G6)),"Finalizado","Verificar")) -> Aguardando
A7: G005 | B7: 46197 | C7: A | D7: Tchequia | E7: Mexico | H7: =IF(AND(F7="",G7=""),"Aguardando",IF(AND(ISNUMBER(F7),ISNUMBER(G7)),"Finalizado","Verificar")) -> Aguardando
A8: G006 | B8: 46197 | C8: A | D8: Africa do Sul | E8: Coreia do Sul | H8: =IF(AND(F8="",G8=""),"Aguardando",IF(AND(ISNUMBER(F8),ISNUMBER(G8)),"Finalizado","Verificar")) -> Aguardando
A9: G007 | B9: 46185 | C9: B | D9: Canada | E9: Bosnia e Herzegovina | H9: =IF(AND(F9="",G9=""),"Aguardando",IF(AND(ISNUMBER(F9),ISNUMBER(G9)),"Finalizado","Verificar")) -> Aguardando
A10: G008 | B10: 46186 | C10: B | D10: Qatar | E10: Suica | H10: =IF(AND(F10="",G10=""),"Aguardando",IF(AND(ISNUMBER(F10),ISNUMBER(G10)),"Finalizado","Verificar")) -> Aguardando
A11: G009 | B11: 46191 | C11: B | D11: Suica | E11: Bosnia e Herzegovina | H11: =IF(AND(F11="",G11=""),"Aguardando",IF(AND(ISNUMBER(F11),ISNUMBER(G11)),"Finalizado","Verificar")) -> Aguardando
A12: G010 | B12: 46191 | C12: B | D12: Canada | E12: Qatar | H12: =IF(AND(F12="",G12=""),"Aguardando",IF(AND(ISNUMBER(F12),ISNUMBER(G12)),"Finalizado","Verificar")) -> Aguardando
A13: G011 | B13: 46197 | C13: B | D13: Suica | E13: Canada | H13: =IF(AND(F13="",G13=""),"Aguardando",IF(AND(ISNUMBER(F13),ISNUMBER(G13)),"Finalizado","Verificar")) -> Aguardando
A14: G012 | B14: 46197 | C14: B | D14: Bosnia e Herzegovina | E14: Qatar | H14: =IF(AND(F14="",G14=""),"Aguardando",IF(AND(ISNUMBER(F14),ISNUMBER(G14)),"Finalizado","Verificar")) -> Aguardando
A15: G013 | B15: 46186 | C15: C | D15: Brasil | E15: Marrocos | H15: =IF(AND(F15="",G15=""),"Aguardando",IF(AND(ISNUMBER(F15),ISNUMBER(G15)),"Finalizado","Verificar")) -> Aguardando
A16: G014 | B16: 46186 | C16: C | D16: Haiti | E16: Escocia | H16: =IF(AND(F16="",G16=""),"Aguardando",IF(AND(ISNUMBER(F16),ISNUMBER(G16)),"Finalizado","Verificar")) -> Aguardando
... A74: G072 | B74: 46200 | C74: L | D74: Croacia | E74: Gana | H74: =IF(AND(F74="",G74=""),"Aguardando",IF(AND(ISNUMBER(F74),ISNUMBER(G74)),"Finalizado","Verificar")) -> Aguardando

Sheet Apostas - Grupos
A1: BOLAO 2026 - APOSTAS: FASE DE GRUPOS
A2: Preencha as celulas AMARELAS com os placares previstos. Role para a direita para ver todos os 72 jogos.
A3: Participante | B3: G001 (A) | D3: G002 (A) | F3: G003 (A) | H3: G004 (A) | J3: G005 (A) | L3: G006 (A) | N3: G007 (B) | P3: G008 (B) | R3: G009 (B) | T3: G010 (B) | V3: G011 (B) | X3: G012 (B) | Z3: G013 (C) | AB3: G014 (C) | AD3: G015 (C) | AF3: G016 (C) | AH3: G017 (C) | AJ3: G018 (C) | AL3: G019 (D) | AN3: G020 (D) | AP3: G021 (D) | AR3: G022 (D) | AT3: G023 (D) | AV3: G024 (D) | AX3: G025 (E) | AZ3: G026 (E) | BB3: G027 (E) | BD3: G028 (E) | BF3: G029 (E) | BH3: G030 (E) | BJ3: G031 (F) | BL3: G032 (F) | BN3: G033 (F) | BP3: G034 (F) | BR3: G035 (F) | BT3: G036 (F) | BV3: G037 (G) | BX3: G038 (G) | BZ3: G039 (G) | CB3: G040 (G) | CD3: G041 (G) | CF3: G042 (G) | CH3: G043 (H) | CJ3: G044 (H) | CL3: G045 (H) | CN3: G046 (H) | CP3: G047 (H) | CR3: G048 (H) | CT3: G049 (I) | CV3: G050 (I) | CX3: G051 (I) | CZ3: G052 (I) | DB3: G053 (I) | DD3: G054 (I) | DF3: G055 (J) | DH3: G056 (J) | DJ3: G057 (J) | DL3: G058 (J) | DN3: G059 (J) | DP3: G060 (J) | DR3: G061 (K) | DT3: G062 (K) | DV3: G063 (K) | DX3: G064 (K) | DZ3: G065 (K) | EB3: G066 (K) | ED3: G067 (L) | EF3: G068 (L) | EH3: G069 (L) | EJ3: G070 (L) | EL3: G071 (L) | EN3: G072 (L)
A4: Nome | B4: Mexico | C4: Africa do Sul | D4: Coreia do Sul | E4: Tchequia | F4: Tchequia | G4: Africa do Sul | H4: Mexico | I4: Coreia do Sul | J4: Tchequia | K4: Mexico | L4: Africa do Sul | M4: Coreia do Sul | N4: Canada | O4: Bosnia e Herzegovina | P4: Qatar | Q4: Suica | R4: Suica | S4: Bosnia e Herzegovina | T4: Canada | U4: Qatar | V4: Suica | W4: Canada | X4: Bosnia e Herzegovina | Y4: Qatar | Z4: Brasil | AA4: Marrocos | AB4: Haiti | AC4: Escocia | AD4: Escocia | AE4: Marrocos | AF4: Brasil | AG4: Haiti | AH4: Escocia | AI4: Brasil | AJ4: Marrocos | AK4: Haiti | AL4: Estados Unidos | AM4: Paraguai | AN4: Australia | AO4: Turquia | AP4: Estados Unidos | AQ4: Australia | AR4: Turquia | AS4: Paraguai | AT4: Turquia | AU4: Estados Unidos | AV4: Paraguai | AW4: Australia | AX4: Alemanha | AY4: Curacao | AZ4: Costa do Marfim | BA4: Equador | BB4: Alemanha | BC4: Costa do Marfim | BD4: Equador | BE4: Curacao | BF4: Equador | BG4: Alemanha | BH4: Curacao | BI4: Costa do Marfim | BJ4: Holanda | BK4: Japao | BL4: Suecia | BM4: Tunisia | BN4: Holanda | BO4: Suecia | BP4: Tunisia | BQ4: Japao | BR4: Japao | BS4: Suecia | BT4: Tunisia | BU4: Holanda | BV4: Belgica | BW4: Egito | BX4: Ira | BY4: Nova Zelandia | BZ4: Belgica | CA4: Ira | CB4: Nova Zelandia | CC4: Egito | CD4: Egito | CE4: Ira | CF4: Nova Zelandia | CG4: Belgica | CH4: Espanha | CI4: Cabo Verde | CJ4: Arabia Saudita | CK4: Uruguai | CL4: Espanha | CM4: Arabia Saudita | CN4: Uruguai | CO4: Cabo Verde | CP4: Cabo Verde | CQ4: Arabia Saudita | CR4: Uruguai | CS4: Espanha | CT4: Franca | CU4: Senegal | CV4: Iraque | CW4: Noruega | CX4: Franca | CY4: Iraque | CZ4: Noruega | DA4: Senegal | DB4: Noruega | DC4: Franca | DD4: Senegal | DE4: Iraque | DF4: Argentina | DG4: Argelia | DH4: Austria | DI4: Jordania | DJ4: Argentina | DK4: Austria | DL4: Jordania | DM4: Argelia | DN4: Argelia | DO4: Austria | DP4: Jordania | DQ4: Argentina | DR4: Portugal | DS4: RD Congo | DT4: Uzbequistao | DU4: Colombia | DV4: Portugal | DW4: Uzbequistao | DX4: Colombia | DY4: RD Congo | DZ4: Colombia | EA4: Portugal | EB4: RD Congo | EC4: Uzbequistao | ED4: Inglaterra | EE4: Croacia | EF4: Gana | EG4: Panama | EH4: Inglaterra | EI4: Gana | EJ4: Panama | EK4: Croacia | EL4: Panama | EM4: Inglaterra | EN4: Croacia | EO4: Gana
A5: Pedro Brandao
A6: Joao Mello
A7: Victor Bethlem
A8: Pedro Herdy

Sheet Apostas - Bonus
A1: BOLAO 2026 - APOSTAS: BONUS
A2: Preencha antes do 1o jogo (11/Jun). Admin preenche linha 4 com resultados reais apos a Copa.
A3: Participante | B3: Artilheiro (10 pts) | C3: Melhor Campanha Grupos (5 pts)
A4: RESULTADO REAL (Admin)
A5: Pedro Brandao
A6: Joao Mello
A7: Victor Bethlem
A8: Pedro Herdy

Sheet Pontuacao - Grupos
A1: PONTUACAO: FASE DE GRUPOS - AUTOMATICO (NAO EDITAR)
A2: 5=placar exato | 3=resultado+saldo correto | 2=apenas resultado correto | 0=errou
A3: Participante | B3: G001 A | C3: G002 A | D3: G003 A | E3: G004 A | F3: G005 A | G3: G006 A | H3: G007 B | I3: G008 B | J3: G009 B | K3: G010 B | L3: G011 B | M3: G012 B | N3: G013 C | O3: G014 C | P3: G015 C | Q3: G016 C | R3: G017 C | S3: G018 C | T3: G019 D | U3: G020 D | V3: G021 D | W3: G022 D | X3: G023 D | Y3: G024 D | Z3: G025 E | AA3: G026 E | AB3: G027 E | AC3: G028 E | AD3: G029 E | AE3: G030 E | AF3: G031 F | AG3: G032 F | AH3: G033 F | AI3: G034 F | AJ3: G035 F | AK3: G036 F | AL3: G037 G | AM3: G038 G | AN3: G039 G | AO3: G040 G | AP3: G041 G | AQ3: G042 G | AR3: G043 H | AS3: G044 H | AT3: G045 H | AU3: G046 H | AV3: G047 H | AW3: G048 H | AX3: G049 I | AY3: G050 I | AZ3: G051 I | BA3: G052 I | BB3: G053 I | BC3: G054 I | BD3: G055 J | BE3: G056 J | BF3: G057 J | BG3: G058 J | BH3: G059 J | BI3: G060 J | BJ3: G061 K | BK3: G062 K | BL3: G063 K | BM3: G064 K | BN3: G065 K | BO3: G066 K | BP3: G067 L | BQ3: G068 L | BR3: G069 L | BS3: G070 L | BT3: G071 L | BU3: G072 L | BV3: TOTAL PTS
A4: Times | B4: Mexico x Africa do Sul | C4: Coreia do Sul x Tchequia | D4: Tchequia x Africa do Sul | E4: Mexico x Coreia do Sul | F4: Tchequia x Mexico | G4: Africa do Sul x Coreia do Sul | H4: Canada x Bosnia e Herzegovina | I4: Qatar x Suica | J4: Suica x Bosnia e Herzegovina | K4: Canada x Qatar | L4: Suica x Canada | M4: Bosnia e Herzegovina x Qatar | N4: Brasil x Marrocos | O4: Haiti x Escocia | P4: Escocia x Marrocos | Q4: Brasil x Haiti | R4: Escocia x Brasil | S4: Marrocos x Haiti | T4: Estados Unidos x Paraguai | U4: Australia x Turquia | V4: Estados Unidos x Australia | W4: Turquia x Paraguai | X4: Turquia x Estados Unidos | Y4: Paraguai x Australia | Z4: Alemanha x Curacao | AA4: Costa do Marfim x Equador | AB4: Alemanha x Costa do Marfim | AC4: Equador x Curacao | AD4: Equador x Alemanha | AE4: Curacao x Costa do Marfim | AF4: Holanda x Japao | AG4: Suecia x Tunisia | AH4: Holanda x Suecia | AI4: Tunisia x Japao | AJ4: Japao x Suecia | AK4: Tunisia x Holanda | AL4: Belgica x Egito | AM4: Ira x Nova Zelandia | AN4: Belgica x Ira | AO4: Nova Zelandia x Egito | AP4: Egito x Ira | AQ4: Nova Zelandia x Belgica | AR4: Espanha x Cabo Verde | AS4: Arabia Saudita x Uruguai | AT4: Espanha x Arabia Saudita | AU4: Uruguai x Cabo Verde | AV4: Cabo Verde x Arabia Saudita | AW4: Uruguai x Espanha | AX4: Franca x Senegal | AY4: Iraque x Noruega | AZ4: Franca x Iraque | BA4: Noruega x Senegal | BB4: Noruega x Franca | BC4: Senegal x Iraque | BD4: Argentina x Argelia | BE4: Austria x Jordania | BF4: Argentina x Austria | BG4: Jordania x Argelia | BH4: Argelia x Austria | BI4: Jordania x Argentina | BJ4: Portugal x RD Congo | BK4: Uzbequistao x Colombia | BL4: Portugal x Uzbequistao | BM4: Colombia x RD Congo | BN4: Colombia x Portugal | BO4: RD Congo x Uzbequistao | BP4: Inglaterra x Croacia | BQ4: Gana x Panama | BR4: Inglaterra x Gana | BS4: Panama x Croacia | BT4: Panama x Inglaterra | BU4: Croacia x Gana
A5: Pedro Brandao | B5: =IF(OR('Jogos - Grupos'!F3="",'Jogos - Grupos'!G3=""),"-",IF(OR('Apostas - Grupos'!B5="",'Apostas - Grupos'!C5=""),0,IF(AND('Apostas - Grupos'!B5='Jogos - Grupos'!F3,'Apostas - Grupos'!C5='Jogos - Grupos'!G3),5,IF(OR(AND('Jogos - Grupos'!F3='Jogos - Grupos'!G3,'Apostas - Grupos'!B5='Apostas - Grupos'!C5),AND('Jogos - Grupos'!F3>'Jogos - Grupos'!G3,'Apostas - Grupos'!B5>'Apostas - Grupos'!C5),AND('Jogos - Grupos'!F3<'Jogos - Grupos'!G3,'Apostas - Grupos'!B5<'Apostas - Grupos'!C5)),IF(('Apostas - Grupos'!B5-'Apostas - Grupos'!C5)=('Jogos - Grupos'!F3-'Jogos - Grupos'!G3),3,2),0)))) -> 0 | C5: =IF(OR('Jogos - Grupos'!F4="",'Jogos - Grupos'!G4=""),"-",IF(OR('Apostas - Grupos'!D5="",'Apostas - Grupos'!E5=""),0,IF(AND('Apostas - Grupos'!D5='Jogos - Grupos'!F4,'Apostas - Grupos'!E5='Jogos - Grupos'!G4),5,IF(OR(AND('Jogos - Grupos'!F4='Jogos - Grupos'!G4,'Apostas - Grupos'!D5='Apostas - Grupos'!E5),AND('Jogos - Grupos'!F4>'Jogos - Grupos'!G4,'Apostas - Grupos'!D5>'Apostas - Grupos'!E5),AND('Jogos - Grupos'!F4<'Jogos - Grupos'!G4,'Apostas - Grupos'!D5<'Apostas - Grupos'!E5)),IF(('Apostas - Grupos'!D5-'Apostas - Grupos'!E5)=('Jogos - Grupos'!F4-'Jogos - Grupos'!G4),3,2),0)))) -> 0 | D5: =IF(OR('Jogos - Grupos'!F5="",'Jogos - Grupos'!G5=""),"-",IF(OR('Apostas - Grupos'!F5="",'Apostas - Grupos'!G5=""),0,IF(AND('Apostas - Grupos'!F5='Jogos - Grupos'!F5,'Apostas - Grupos'!G5='Jogos - Grupos'!G5),5,IF(OR(AND('Jogos - Grupos'!F5='Jogos - Grupos'!G5,'Apostas - Grupos'!F5='Apostas - Grupos'!G5),AND('Jogos - Grupos'!F5>'Jogos - Grupos'!G5,'Apostas - Grupos'!F5>'Apostas - Grupos'!G5),AND('Jogos - Grupos'!F5<'Jogos - Grupos'!G5,'Apostas - Grupos'!F5<'Apostas - Grupos'!G5)),IF(('Apostas - Grupos'!F5-'Apostas - Grupos'!G5)=('Jogos - Grupos'!F5-'Jogos - Grupos'!G5),3,2),0)))) -> - | E5: =IF(OR('Jogos - Grupos'!F6="",'Jogos - Grupos'!G6=""),"-",IF(OR('Apostas - Grupos'!H5="",'Apostas - Grupos'!I5=""),0,IF(AND('Apostas - Grupos'!H5='Jogos - Grupos'!F6,'Apostas - Grupos'!I5='Jogos - Grupos'!G6),5,IF(OR(AND('Jogos - Grupos'!F6='Jogos - Grupos'!G6,'Apostas - Grupos'!H5='Apostas - Grupos'!I5),AND('Jogos - Grupos'!F6>'Jogos - Grupos'!G6,'Apostas - Grupos'!H5>'Apostas - Grupos'!I5),AND('Jogos - Grupos'!F6<'Jogos - Grupos'!G6,'Apostas - Grupos'!H5<'Apostas - Grupos'!I5)),IF(('Apostas - Grupos'!H5-'Apostas - Grupos'!I5)=('Jogos - Grupos'!F6-'Jogos - Grupos'!G6),3,2),0)))) -> - | F5: =IF(OR('Jogos - Grupos'!F7="",'Jogos - Grupos'!G7=""),"-",IF(OR('Apostas - Grupos'!J5="",'Apostas - Grupos'!K5=""),0,IF(AND('Apostas - Grupos'!J5='Jogos - Grupos'!F7,'Apostas - Grupos'!K5='Jogos - Grupos'!G7),5,IF(OR(AND('Jogos - Grupos'!F7='Jogos - Grupos'!G7,'Apostas - Grupos'!J5='Apostas - Grupos'!K5),AND('Jogos - Grupos'!F7>'Jogos - Grupos'!G7,'Apostas - Grupos'!J5>'Apostas - Grupos'!K5),AND('Jogos - Grupos'!F7<'Jogos - Grupos'!G7,'Apostas - Grupos'!J5<'Apostas - Grupos'!K5)),IF(('Apostas - Grupos'!J5-'Apostas - Grupos'!K5)=('Jogos - Grupos'!F7-'Jogos - Grupos'!G7),3,2),0)))) -> - | G5: =IF(OR('Jogos - Grupos'!F8="",'Jogos - Grupos'!G8=""),"-",IF(OR('Apostas - Grupos'!L5="",'Apostas - Grupos'!M5=""),0,IF(AND('Apostas - Grupos'!L5='Jogos - Grupos'!F8,'Apostas - Grupos'!M5='Jogos - Grupos'!G8),5,IF(OR(AND('Jogos - Grupos'!F8='Jogos - Grupos'!G8,'Apostas - Grupos'!L5='Apostas - Grupos'!M5),AND('Jogos - Grupos'!F8>'Jogos - Grupos'!G8,'Apostas - Grupos'!L5>'Apostas - Grupos'!M5),AND('Jogos - Grupos'!F8<'Jogos - Grupos'!G8,'Apostas - Grupos'!L5<'Apostas - Grupos'!M5)),IF(('Apostas - Grupos'!L5-'Apostas - Grupos'!M5)=('Jogos - Grupos'!F8-'Jogos - Grupos'!G8),3,2),0)))) -> - | H5: =IF(OR('Jogos - Grupos'!F9="",'Jogos - Grupos'!G9=""),"-",IF(OR('Apostas - Grupos'!N5="",'Apostas - Grupos'!O5=""),0,IF(AND('Apostas - Grupos'!N5='Jogos - Grupos'!F9,'Apostas - Grupos'!O5='Jogos - Grupos'!G9),5,IF(OR(AND('Jogos - Grupos'!F9='Jogos - Grupos'!G9,'Apostas - Grupos'!N5='Apostas - Grupos'!O5),AND('Jogos - Grupos'!F9>'Jogos - Grupos'!G9,'Apostas - Grupos'!N5>'Apostas - Grupos'!O5),AND('Jogos - Grupos'!F9<'Jogos - Grupos'!G9,'Apostas - Grupos'!N5<'Apostas - Grupos'!O5)),IF(('Apostas - Grupos'!N5-'Apostas - Grupos'!O5)=('Jogos - Grupos'!F9-'Jogos - Grupos'!G9),3,2),0)))) -> - | I5: =IF(OR('Jogos - Grupos'!F10="",'Jogos - Grupos'!G10=""),"-",IF(OR('Apostas - Grupos'!P5="",'Apostas - Grupos'!Q5=""),0,IF(AND('Apostas - Grupos'!P5='Jogos - Grupos'!F10,'Apostas - Grupos'!Q5='Jogos - Grupos'!G10),5,IF(OR(AND('Jogos - Grupos'!F10='Jogos - Grupos'!G10,'Apostas - Grupos'!P5='Apostas - Grupos'!Q5),AND('Jogos - Grupos'!F10>'Jogos - Grupos'!G10,'Apostas - Grupos'!P5>'Apostas - Grupos'!Q5),AND('Jogos - Grupos'!F10<'Jogos - Grupos'!G10,'Apostas - Grupos'!P5<'Apostas - Grupos'!Q5)),IF(('Apostas - Grupos'!P5-'Apostas - Grupos'!Q5)=('Jogos - Grupos'!F10-'Jogos - Grupos'!G10),3,2),0)))) -> - | J5: =IF(OR('Jogos - Grupos'!F11="",'Jogos - Grupos'!G11=""),"-",IF(OR('Apostas - Grupos'!R5="",'Apostas - Grupos'!S5=""),0,IF(AND('Apostas - Grupos'!R5='Jogos - Grupos'!F11,'Apostas - Grupos'!S5='Jogos - Grupos'!G11),5,IF(OR(AND('Jogos - Grupos'!F11='Jogos - Grupos'!G11,'Apostas - Grupos'!R5='Apostas - Grupos'!S5),AND('Jogos - Grupos'!F11>'Jogos - Grupos'!G11,'Apostas - Grupos'!R5>'Apostas - Grupos'!S5),AND('Jogos - Grupos'!F11<'Jogos - Grupos'!G11,'Apostas - Grupos'!R5<'Apostas - Grupos'!S5)),IF(('Apostas - Grupos'!R5-'Apostas - Grupos'!S5)=('Jogos - Grupos'!F11-'Jogos - Grupos'!G11),3,2),0)))) -> - | K5: =IF(OR('Jogos - Grupos'!F12="",'Jogos - Grupos'!G12=""),"-",IF(OR('Apostas - Grupos'!T5="",'Apostas - Grupos'!U5=""),0,IF(AND('Apostas - Grupos'!T5='Jogos - Grupos'!F12,'Apostas - Grupos'!U5='Jogos - Grupos'!G12),5,IF(OR(AND('Jogos - Grupos'!F12='Jogos - Grupos'!G12,'Apostas - Grupos'!T5='Apostas - Grupos'!U5),AND('Jogos - Grupos'!F12>'Jogos - Grupos'!G12,'Apostas - Grupos'!T5>'Apostas - Grupos'!U5),AND('Jogos - Grupos'!F12<'Jogos - Grupos'!G12,'Apostas - Grupos'!T5<'Apostas - Grupos'!U5)),IF(('Apostas - Grupos'!T5-'Apostas - Grupos'!U5)=('Jogos - Grupos'!F12-'Jogos - Grupos'!G12),3,2),0)))) -> - | L5: =IF(OR('Jogos - Grupos'!F13="",'Jogos - Grupos'!G13=""),"-",IF(OR('Apostas - Grupos'!V5="",'Apostas - Grupos'!W5=""),0,IF(AND('Apostas - Grupos'!V5='Jogos - Grupos'!F13,'Apostas - Grupos'!W5='Jogos - Grupos'!G13),5,IF(OR(AND('Jogos - Grupos'!F13='Jogos - Grupos'!G13,'Apostas - Grupos'!V5='Apostas - Grupos'!W5),AND('Jogos - Grupos'!F13>'Jogos - Grupos'!G13,'Apostas - Grupos'!V5>'Apostas - Grupos'!W5),AND('Jogos - Grupos'!F13<'Jogos - Grupos'!G13,'Apostas - Grupos'!V5<'Apostas - Grupos'!W5)),IF(('Apostas - Grupos'!V5-'Apostas - Grupos'!W5)=('Jogos - Grupos'!F13-'Jogos - Grupos'!G13),3,2),0)))) -> - | M5: =IF(OR('Jogos - Grupos'!F14="",'Jogos - Grupos'!G14=""),"-",IF(OR('Apostas - Grupos'!X5="",'Apostas - Grupos'!Y5=""),0,IF(AND('Apostas - Grupos'!X5='Jogos - Grupos'!F14,'Apostas - Grupos'!Y5='Jogos - Grupos'!G14),5,IF(OR(AND('Jogos - Grupos'!F14='Jogos - Grupos'!G14,'Apostas - Grupos'!X5='Apostas - Grupos'!Y5),AND('Jogos - Grupos'!F14>'Jogos - Grupos'!G14,'Apostas - Grupos'!X5>'Apostas - Grupos'!Y5),AND('Jogos - Grupos'!F14<'Jogos - Grupos'!G14,'Apostas - Grupos'!X5<'Apostas - Grupos'!Y5)),IF(('Apostas - Grupos'!X5-'Apostas - Grupos'!Y5)=('Jogos - Grupos'!F14-'Jogos - Grupos'!G14),3,2),0)))) -> - | N5: =IF(OR('Jogos - Grupos'!F15="",'Jogos - Grupos'!G15=""),"-",IF(OR('Apostas - Grupos'!Z5="",'Apostas - Grupos'!AA5=""),0,IF(AND('Apostas - Grupos'!Z5='Jogos - Grupos'!F15,'Apostas - Grupos'!AA5='Jogos - Grupos'!G15),5,IF(OR(AND('Jogos - Grupos'!F15='Jogos - Grupos'!G15,'Apostas - Grupos'!Z5='Apostas - Grupos'!AA5),AND('Jogos - Grupos'!F15>'Jogos - Grupos'!G15,'Apostas - Grupos'!Z5>'Apostas - Grupos'!AA5),AND('Jogos - Grupos'!F15<'Jogos - Grupos'!G15,'Apostas - Grupos'!Z5<'Apostas - Grupos'!AA5)),IF(('Apostas - Grupos'!Z5-'Apostas - Grupos'!AA5)=('Jogos - Grupos'!F15-'Jogos - Grupos'!G15),3,2),0)))) -> - | O5: =IF(OR('Jogos - Grupos'!F16="",'Jogos - Grupos'!G16=""),"-",IF(OR('Apostas - Grupos'!AB5="",'Apostas - Grupos'!AC5=""),0,IF(AND('Apostas - Grupos'!AB5='Jogos - Grupos'!F16,'Apostas - Grupos'!AC5='Jogos - Grupos'!G16),5,IF(OR(AND('Jogos - Grupos'!F16='Jogos - Grupos'!G16,'Apostas - Grupos'!AB5='Apostas - Grupos'!AC5),AND('Jogos - Grupos'!F16>'Jogos - Grupos'!G16,'Apostas - Grupos'!AB5>'Apostas - Grupos'!AC5),AND('Jogos - Grupos'!F16<'Jogos - Grupos'!G16,'Apostas - Grupos'!AB5<'Apostas - Grupos'!AC5)),IF(('Apostas - Grupos'!AB5-'Apostas - Grupos'!AC5)=('Jogos - Grupos'!F16-'Jogos - Grupos'!G16),3,2),0)))) -> - | P5: =IF(OR('Jogos - Grupos'!F17="",'Jogos - Grupos'!G17=""),"-",IF(OR('Apostas - Grupos'!AD5="",'Apostas - Grupos'!AE5=""),0,IF(AND('Apostas - Grupos'!AD5='Jogos - Grupos'!F17,'Apostas - Grupos'!AE5='Jogos - Grupos'!G17),5,IF(OR(AND('Jogos - Grupos'!F17='Jogos - Grupos'!G17,'Apostas - Grupos'!AD5='Apostas - Grupos'!AE5),AND('Jogos - Grupos'!F17>'Jogos - Grupos'!G17,'Apostas - Grupos'!AD5>'Apostas - Grupos'!AE5),AND('Jogos - Grupos'!F17<'Jogos - Grupos'!G17,'Apostas - Grupos'!AD5<'Apostas - Grupos'!AE5)),IF(('Apostas - Grupos'!AD5-'Apostas - Grupos'!AE5)=('Jogos - Grupos'!F17-'Jogos - Grupos'!G17),3,2),0)))) -> - | Q5: =IF(OR('Jogos - Grupos'!F18="",'Jogos - Grupos'!G18=""),"-",IF(OR('Apostas - Grupos'!AF5="",'Apostas - Grupos'!AG5=""),0,IF(AND('Apostas - Grupos'!AF5='Jogos - Grupos'!F18,'Apostas - Grupos'!AG5='Jogos - Grupos'!G18),5,IF(OR(AND('Jogos - Grupos'!F18='Jogos - Grupos'!G18,'Apostas - Grupos'!AF5='Apostas - Grupos'!AG5),AND('Jogos - Grupos'!F18>'Jogos - Grupos'!G18,'Apostas - Grupos'!AF5>'Apostas - Grupos'!AG5),AND('Jogos - Grupos'!F18<'Jogos - Grupos'!G18,'Apostas - Grupos'!AF5<'Apostas - Grupos'!AG5)),IF(('Apostas - Grupos'!AF5-'Apostas - Grupos'!AG5)=('Jogos - Grupos'!F18-'Jogos - Grupos'!G18),3,2),0)))) -> - | R5: =IF(OR('Jogos - Grupos'!F19="",'Jogos - Grupos'!G19=""),"-",IF(OR('Apostas - Grupos'!AH5="",'Apostas - Grupos'!AI5=""),0,IF(AND('Apostas - Grupos'!AH5='Jogos - Grupos'!F19,'Apostas - Grupos'!AI5='Jogos - Grupos'!G19),5,IF(OR(AND('Jogos - Grupos'!F19='Jogos - Grupos'!G19,'Apostas - Grupos'!AH5='Apostas - Grupos'!AI5),AND('Jogos - Grupos'!F19>'Jogos - Grupos'!G19,'Apostas - Grupos'!AH5>'Apostas - Grupos'!AI5),AND('Jogos - Grupos'!F19<'Jogos - Grupos'!G19,'Apostas - Grupos'!AH5<'Apostas - Grupos'!AI5)),IF(('Apostas - Grupos'!AH5-'Apostas - Grupos'!AI5)=('Jogos - Grupos'!F19-'Jogos - Grupos'!G19),3,2),0)))) -> - | S5: =IF(OR('Jogos - Grupos'!F20="",'Jogos - Grupos'!G20=""),"-",IF(OR('Apostas - Grupos'!AJ5="",'Apostas - Grupos'!AK5=""),0,IF(AND('Apostas - Grupos'!AJ5='Jogos - Grupos'!F20,'Apostas - Grupos'!AK5='Jogos - Grupos'!G20),5,IF(OR(AND('Jogos - Grupos'!F20='Jogos - Grupos'!G20,'Apostas - Grupos'!AJ5='Apostas - Grupos'!AK5),AND('Jogos - Grupos'!F20>'Jogos - Grupos'!G20,'Apostas - Grupos'!AJ5>'Apostas - Grupos'!AK5),AND('Jogos - Grupos'!F20<'Jogos - Grupos'!G20,'Apostas - Grupos'!AJ5<'Apostas - Grupos'!AK5)),IF(('Apostas - Grupos'!AJ5-'Apostas - Grupos'!AK5)=('Jogos - Grupos'!F20-'Jogos - Grupos'!G20),3,2),0)))) -> - | T5: =IF(OR('Jogos - Grupos'!F21="",'Jogos - Grupos'!G21=""),"-",IF(OR('Apostas - Grupos'!AL5="",'Apostas - Grupos'!AM5=""),0,IF(AND('Apostas - Grupos'!AL5='Jogos - Grupos'!F21,'Apostas - Grupos'!AM5='Jogos - Grupos'!G21),5,IF(OR(AND('Jogos - Grupos'!F21='Jogos - Grupos'!G21,'Apostas - Grupos'!AL5='Apostas - Grupos'!AM5),AND('Jogos - Grupos'!F21>'Jogos - Grupos'!G21,'Apostas - Grupos'!AL5>'Apostas - Grupos'!AM5),AND('Jogos - Grupos'!F21<'Jogos - Grupos'!G21,'Apostas - Grupos'!AL5<'Apostas - Grupos'!AM5)),IF(('Apostas - Grupos'!AL5-'Apostas - Grupos'!AM5)=('Jogos - Grupos'!F21-'Jogos - Grupos'!G21),3,2),0)))) -> - | U5: =IF(OR('Jogos - Grupos'!F22="",'Jogos - Grupos'!G22=""),"-",IF(OR('Apostas - Grupos'!AN5="",'Apostas - Grupos'!AO5=""),0,IF(AND('Apostas - Grupos'!AN5='Jogos - Grupos'!F22,'Apostas - Grupos'!AO5='Jogos - Grupos'!G22),5,IF(OR(AND('Jogos - Grupos'!F22='Jogos - Grupos'!G22,'Apostas - Grupos'!AN5='Apostas - Grupos'!AO5),AND('Jogos - Grupos'!F22>'Jogos - Grupos'!G22,'Apostas - Grupos'!AN5>'Apostas - Grupos'!AO5),AND('Jogos - Grupos'!F22<'Jogos - Grupos'!G22,'Apostas - Grupos'!AN5<'Apostas - Grupos'!AO5)),IF(('Apostas - Grupos'!AN5-'Apostas - Grupos'!AO5)=('Jogos - Grupos'!F22-'Jogos - Grupos'!G22),3,2),0)))) -> - | V5: =IF(OR('Jogos - Grupos'!F23="",'Jogos - Grupos'!G23=""),"-",IF(OR('Apostas - Grupos'!AP5="",'Apostas - Grupos'!AQ5=""),0,IF(AND('Apostas - Grupos'!AP5='Jogos - Grupos'!F23,'Apostas - Grupos'!AQ5='Jogos - Grupos'!G23),5,IF(OR(AND('Jogos - Grupos'!F23='Jogos - Grupos'!G23,'Apostas - Grupos'!AP5='Apostas - Grupos'!AQ5),AND('Jogos - Grupos'!F23>'Jogos - Grupos'!G23,'Apostas - Grupos'!AP5>'Apostas - Grupos'!AQ5),AND('Jogos - Grupos'!F23<'Jogos - Grupos'!G23,'Apostas - Grupos'!AP5<'Apostas - Grupos'!AQ5)),IF(('Apostas - Grupos'!AP5-'Apostas - Grupos'!AQ5)=('Jogos - Grupos'!F23-'Jogos - Grupos'!G23),3,2),0)))) -> - | W5: =IF(OR('Jogos - Grupos'!F24="",'Jogos - Grupos'!G24=""),"-",IF(OR('Apostas - Grupos'!AR5="",'Apostas - Grupos'!AS5=""),0,IF(AND('Apostas - Grupos'!AR5='Jogos - Grupos'!F24,'Apostas - Grupos'!AS5='Jogos - Grupos'!G24),5,IF(OR(AND('Jogos - Grupos'!F24='Jogos - Grupos'!G24,'Apostas - Grupos'!AR5='Apostas - Grupos'!AS5),AND('Jogos - Grupos'!F24>'Jogos - Grupos'!G24,'Apostas - Grupos'!AR5>'Apostas - Grupos'!AS5),AND('Jogos - Grupos'!F24<'Jogos - Grupos'!G24,'Apostas - Grupos'!AR5<'Apostas - Grupos'!AS5)),IF(('Apostas - Grupos'!AR5-'Apostas - Grupos'!AS5)=('Jogos - Grupos'!F24-'Jogos - Grupos'!G24),3,2),0)))) -> - | X5: =IF(OR('Jogos - Grupos'!F25="",'Jogos - Grupos'!G25=""),"-",IF(OR('Apostas - Grupos'!AT5="",'Apostas - Grupos'!AU5=""),0,IF(AND('Apostas - Grupos'!AT5='Jogos - Grupos'!F25,'Apostas - Grupos'!AU5='Jogos - Grupos'!G25),5,IF(OR(AND('Jogos - Grupos'!F25='Jogos - Grupos'!G25,'Apostas - Grupos'!AT5='Apostas - Grupos'!AU5),AND('Jogos - Grupos'!F25>'Jogos - Grupos'!G25,'Apostas - Grupos'!AT5>'Apostas - Grupos'!AU5),AND('Jogos - Grupos'!F25<'Jogos - Grupos'!G25,'Apostas - Grupos'!AT5<'Apostas - Grupos'!AU5)),IF(('Apostas - Grupos'!AT5-'Apostas - Grupos'!AU5)=('Jogos - Grupos'!F25-'Jogos - Grupos'!G25),3,2),0)))) -> - | Y5: =IF(OR('Jogos - Grupos'!F26="",'Jogos - Grupos'!G26=""),"-",IF(OR('Apostas - Grupos'!AV5="",'Apostas - Grupos'!AW5=""),0,IF(AND('Apostas - Grupos'!AV5='Jogos - Grupos'!F26,'Apostas - Grupos'!AW5='Jogos - Grupos'!G26),5,IF(OR(AND('Jogos - Grupos'!F26='Jogos - Grupos'!G26,'Apostas - Grupos'!AV5='Apostas - Grupos'!AW5),AND('Jogos - Grupos'!F26>'Jogos - Grupos'!G26,'Apostas - Grupos'!AV5>'Apostas - Grupos'!AW5),AND('Jogos - Grupos'!F26<'Jogos - Grupos'!G26,'Apostas - Grupos'!AV5<'Apostas - Grupos'!AW5)),IF(('Apostas - Grupos'!AV5-'Apostas - Grupos'!AW5)=('Jogos - Grupos'!F26-'Jogos - Grupos'!G26),3,2),0)))) -> - | Z5: =IF(OR('Jogos - Grupos'!F27="",'Jogos - Grupos'!G27=""),"-",IF(OR('Apostas - Grupos'!AX5="",'Apostas - Grupos'!AY5=""),0,IF(AND('Apostas - Grupos'!AX5='Jogos - Grupos'!F27,'Apostas - Grupos'!AY5='Jogos - Grupos'!G27),5,IF(OR(AND('Jogos - Grupos'!F27='Jogos - Grupos'!G27,'Apostas - Grupos'!AX5='Apostas - Grupos'!AY5),AND('Jogos - Grupos'!F27>'Jogos - Grupos'!G27,'Apostas - Grupos'!AX5>'Apostas - Grupos'!AY5),AND('Jogos - Grupos'!F27<'Jogos - Grupos'!G27,'Apostas - Grupos'!AX5<'Apostas - Grupos'!AY5)),IF(('Apostas - Grupos'!AX5-'Apostas - Grupos'!AY5)=('Jogos - Grupos'!F27-'Jogos - Grupos'!G27),3,2),0)))) -> - | AA5: =IF(OR('Jogos - Grupos'!F28="",'Jogos - Grupos'!G28=""),"-",IF(OR('Apostas - Grupos'!AZ5="",'Apostas - Grupos'!BA5=""),0,IF(AND('Apostas - Grupos'!AZ5='Jogos - Grupos'!F28,'Apostas - Grupos'!BA5='Jogos - Grupos'!G28),5,IF(OR(AND('Jogos - Grupos'!F28='Jogos - Grupos'!G28,'Apostas - Grupos'!AZ5='Apostas - Grupos'!BA5),AND('Jogos - Grupos'!F28>'Jogos - Grupos'!G28,'Apostas - Grupos'!AZ5>'Apostas - Grupos'!BA5),AND('Jogos - Grupos'!F28<'Jogos - Grupos'!G28,'Apostas - Grupos'!AZ5<'Apostas - Grupos'!BA5)),IF(('Apostas - Grupos'!AZ5-'Apostas - Grupos'!BA5)=('Jogos - Grupos'!F28-'Jogos - Grupos'!G28),3,2),0)))) -> - | AB5: =IF(OR('Jogos - Grupos'!F29="",'Jogos - Grupos'!G29=""),"-",IF(OR('Apostas - Grupos'!BB5="",'Apostas - Grupos'!BC5=""),0,IF(AND('Apostas - Grupos'!BB5='Jogos - Grupos'!F29,'Apostas - Grupos'!BC5='Jogos - Grupos'!G29),5,IF(OR(AND('Jogos - Grupos'!F29='Jogos - Grupos'!G29,'Apostas - Grupos'!BB5='Apostas - Grupos'!BC5),AND('Jogos - Grupos'!F29>'Jogos - Grupos'!G29,'Apostas - Grupos'!BB5>'Apostas - Grupos'!BC5),AND('Jogos - Grupos'!F29<'Jogos - Grupos'!G29,'Apostas - Grupos'!BB5<'Apostas - Grupos'!BC5)),IF(('Apostas - Grupos'!BB5-'Apostas - Grupos'!BC5)=('Jogos - Grupos'!F29-'Jogos - Grupos'!G29),3,2),0)))) -> - | AC5: =IF(OR('Jogos - Grupos'!F30="",'Jogos - Grupos'!G30=""),"-",IF(OR('Apostas - Grupos'!BD5="",'Apostas - Grupos'!BE5=""),0,IF(AND('Apostas - Grupos'!BD5='Jogos - Grupos'!F30,'Apostas - Grupos'!BE5='Jogos - Grupos'!G30),5,IF(OR(AND('Jogos - Grupos'!F30='Jogos - Grupos'!G30,'Apostas - Grupos'!BD5='Apostas - Grupos'!BE5),AND('Jogos - Grupos'!F30>'Jogos - Grupos'!G30,'Apostas - Grupos'!BD5>'Apostas - Grupos'!BE5),AND('Jogos - Grupos'!F30<'Jogos - Grupos'!G30,'Apostas - Grupos'!BD5<'Apostas - Grupos'!BE5)),IF(('Apostas - Grupos'!BD5-'Apostas - Grupos'!BE5)=('Jogos - Grupos'!F30-'Jogos - Grupos'!G30),3,2),0)))) -> - | AD5: =IF(OR('Jogos - Grupos'!F31="",'Jogos - Grupos'!G31=""),"-",IF(OR('Apostas - Grupos'!BF5="",'Apostas - Grupos'!BG5=""),0,IF(AND('Apostas - Grupos'!BF5='Jogos - Grupos'!F31,'Apostas - Grupos'!BG5='Jogos - Grupos'!G31),5,IF(OR(AND('Jogos - Grupos'!F31='Jogos - Grupos'!G31,'Apostas - Grupos'!BF5='Apostas - Grupos'!BG5),AND('Jogos - Grupos'!F31>'Jogos - Grupos'!G31,'Apostas - Grupos'!BF5>'Apostas - Grupos'!BG5),AND('Jogos - Grupos'!F31<'Jogos - Grupos'!G31,'Apostas - Grupos'!BF5<'Apostas - Grupos'!BG5)),IF(('Apostas - Grupos'!BF5-'Apostas - Grupos'!BG5)=('Jogos - Grupos'!F31-'Jogos - Grupos'!G31),3,2),0)))) -> - | AE5: =IF(OR('Jogos - Grupos'!F32="",'Jogos - Grupos'!G32=""),"-",IF(OR('Apostas - Grupos'!BH5="",'Apostas - Grupos'!BI5=""),0,IF(AND('Apostas - Grupos'!BH5='Jogos - Grupos'!F32,'Apostas - Grupos'!BI5='Jogos - Grupos'!G32),5,IF(OR(AND('Jogos - Grupos'!F32='Jogos - Grupos'!G32,'Apostas - Grupos'!BH5='Apostas - Grupos'!BI5),AND('Jogos - Grupos'!F32>'Jogos - Grupos'!G32,'Apostas - Grupos'!BH5>'Apostas - Grupos'!BI5),AND('Jogos - Grupos'!F32<'Jogos - Grupos'!G32,'Apostas - Grupos'!BH5<'Apostas - Grupos'!BI5)),IF(('Apostas - Grupos'!BH5-'Apostas - Grupos'!BI5)=('Jogos - Grupos'!F32-'Jogos - Grupos'!G32),3,2),0)))) -> - | AF5: =IF(OR('Jogos - Grupos'!F33="",'Jogos - Grupos'!G33=""),"-",IF(OR('Apostas - Grupos'!BJ5="",'Apostas - Grupos'!BK5=""),0,IF(AND('Apostas - Grupos'!BJ5='Jogos - Grupos'!F33,'Apostas - Grupos'!BK5='Jogos - Grupos'!G33),5,IF(OR(AND('Jogos - Grupos'!F33='Jogos - Grupos'!G33,'Apostas - Grupos'!BJ5='Apostas - Grupos'!BK5),AND('Jogos - Grupos'!F33>'Jogos - Grupos'!G33,'Apostas - Grupos'!BJ5>'Apostas - Grupos'!BK5),AND('Jogos - Grupos'!F33<'Jogos - Grupos'!G33,'Apostas - Grupos'!BJ5<'Apostas - Grupos'!BK5)),IF(('Apostas - Grupos'!BJ5-'Apostas - Grupos'!BK5)=('Jogos - Grupos'!F33-'Jogos - Grupos'!G33),3,2),0)))) -> - | AG5: =IF(OR('Jogos - Grupos'!F34="",'Jogos - Grupos'!G34=""),"-",IF(OR('Apostas - Grupos'!BL5="",'Apostas - Grupos'!BM5=""),0,IF(AND('Apostas - Grupos'!BL5='Jogos - Grupos'!F34,'Apostas - Grupos'!BM5='Jogos - Grupos'!G34),5,IF(OR(AND('Jogos - Grupos'!F34='Jogos - Grupos'!G34,'Apostas - Grupos'!BL5='Apostas - Grupos'!BM5),AND('Jogos - Grupos'!F34>'Jogos - Grupos'!G34,'Apostas - Grupos'!BL5>'Apostas - Grupos'!BM5),AND('Jogos - Grupos'!F34<'Jogos - Grupos'!G34,'Apostas - Grupos'!BL5<'Apostas - Grupos'!BM5)),IF(('Apostas - Grupos'!BL5-'Apostas - Grupos'!BM5)=('Jogos - Grupos'!F34-'Jogos - Grupos'!G34),3,2),0)))) -> - | AH5: =IF(OR('Jogos - Grupos'!F35="",'Jogos - Grupos'!G35=""),"-",IF(OR('Apostas - Grupos'!BN5="",'Apostas - Grupos'!BO5=""),0,IF(AND('Apostas - Grupos'!BN5='Jogos - Grupos'!F35,'Apostas - Grupos'!BO5='Jogos - Grupos'!G35),5,IF(OR(AND('Jogos - Grupos'!F35='Jogos - Grupos'!G35,'Apostas - Grupos'!BN5='Apostas - Grupos'!BO5),AND('Jogos - Grupos'!F35>'Jogos - Grupos'!G35,'Apostas - Grupos'!BN5>'Apostas - Grupos'!BO5),AND('Jogos - Grupos'!F35<'Jogos - Grupos'!G35,'Apostas - Grupos'!BN5<'Apostas - Grupos'!BO5)),IF(('Apostas - Grupos'!BN5-'Apostas - Grupos'!BO5)=('Jogos - Grupos'!F35-'Jogos - Grupos'!G35),3,2),0)))) -> - | AI5: =IF(OR('Jogos - Grupos'!F36="",'Jogos - Grupos'!G36=""),"-",IF(OR('Apostas - Grupos'!BP5="",'Apostas - Grupos'!BQ5=""),0,IF(AND('Apostas - Grupos'!BP5='Jogos - Grupos'!F36,'Apostas - Grupos'!BQ5='Jogos - Grupos'!G36),5,IF(OR(AND('Jogos - Grupos'!F36='Jogos - Grupos'!G36,'Apostas - Grupos'!BP5='Apostas - Grupos'!BQ5),AND('Jogos - Grupos'!F36>'Jogos - Grupos'!G36,'Apostas - Grupos'!BP5>'Apostas - Grupos'!BQ5),AND('Jogos - Grupos'!F36<'Jogos - Grupos'!G36,'Apostas - Grupos'!BP5<'Apostas - Grupos'!BQ5)),IF(('Apostas - Grupos'!BP5-'Apostas - Grupos'!BQ5)=('Jogos - Grupos'!F36-'Jogos - Grupos'!G36),3,2),0)))) -> - | AJ5: =IF(OR('Jogos - Grupos'!F37="",'Jogos - Grupos'!G37=""),"-",IF(OR('Apostas - Grupos'!BR5="",'Apostas - Grupos'!BS5=""),0,IF(AND('Apostas - Grupos'!BR5='Jogos - Grupos'!F37,'Apostas - Grupos'!BS5='Jogos - Grupos'!G37),5,IF(OR(AND('Jogos - Grupos'!F37='Jogos - Grupos'!G37,'Apostas - Grupos'!BR5='Apostas - Grupos'!BS5),AND('Jogos - Grupos'!F37>'Jogos - Grupos'!G37,'Apostas - Grupos'!BR5>'Apostas - Grupos'!BS5),AND('Jogos - Grupos'!F37<'Jogos - Grupos'!G37,'Apostas - Grupos'!BR5<'Apostas - Grupos'!BS5)),IF(('Apostas - Grupos'!BR5-'Apostas - Grupos'!BS5)=('Jogos - Grupos'!F37-'Jogos - Grupos'!G37),3,2),0)))) -> - | AK5: =IF(OR('Jogos - Grupos'!F38="",'Jogos - Grupos'!G38=""),"-",IF(OR('Apostas - Grupos'!BT5="",'Apostas - Grupos'!BU5=""),0,IF(AND('Apostas - Grupos'!BT5='Jogos - Grupos'!F38,'Apostas - Grupos'!BU5='Jogos - Grupos'!G38),5,IF(OR(AND('Jogos - Grupos'!F38='Jogos - Grupos'!G38,'Apostas - Grupos'!BT5='Apostas - Grupos'!BU5),AND('Jogos - Grupos'!F38>'Jogos - Grupos'!G38,'Apostas - Grupos'!BT5>'Apostas - Grupos'!BU5),AND('Jogos - Grupos'!F38<'Jogos - Grupos'!G38,'Apostas - Grupos'!BT5<'Apostas - Grupos'!BU5)),IF(('Apostas - Grupos'!BT5-'Apostas - Grupos'!BU5)=('Jogos - Grupos'!F38-'Jogos - Grupos'!G38),3,2),0)))) -> - | AL5: =IF(OR('Jogos - Grupos'!F39="",'Jogos - Grupos'!G39=""),"-",IF(OR('Apostas - Grupos'!BV5="",'Apostas - Grupos'!BW5=""),0,IF(AND('Apostas - Grupos'!BV5='Jogos - Grupos'!F39,'Apostas - Grupos'!BW5='Jogos - Grupos'!G39),5,IF(OR(AND('Jogos - Grupos'!F39='Jogos - Grupos'!G39,'Apostas - Grupos'!BV5='Apostas - Grupos'!BW5),AND('Jogos - Grupos'!F39>'Jogos - Grupos'!G39,'Apostas - Grupos'!BV5>'Apostas - Grupos'!BW5),AND('Jogos - Grupos'!F39<'Jogos - Grupos'!G39,'Apostas - Grupos'!BV5<'Apostas - Grupos'!BW5)),IF(('Apostas - Grupos'!BV5-'Apostas - Grupos'!BW5)=('Jogos - Grupos'!F39-'Jogos - Grupos'!G39),3,2),0)))) -> - | AM5: =IF(OR('Jogos - Grupos'!F40="",'Jogos - Grupos'!G40=""),"-",IF(OR('Apostas - Grupos'!BX5="",'Apostas - Grupos'!BY5=""),0,IF(AND('Apostas - Grupos'!BX5='Jogos - Grupos'!F40,'Apostas - Grupos'!BY5='Jogos - Grupos'!G40),5,IF(OR(AND('Jogos - Grupos'!F40='Jogos - Grupos'!G40,'Apostas - Grupos'!BX5='Apostas - Grupos'!BY5),AND('Jogos - Grupos'!F40>'Jogos - Grupos'!G40,'Apostas - Grupos'!BX5>'Apostas - Grupos'!BY5),AND('Jogos - Grupos'!F40<'Jogos - Grupos'!G40,'Apostas - Grupos'!BX5<'Apostas - Grupos'!BY5)),IF(('Apostas - Grupos'!BX5-'Apostas - Grupos'!BY5)=('Jogos - Grupos'!F40-'Jogos - Grupos'!G40),3,2),0)))) -> - | AN5: =IF(OR('Jogos - Grupos'!F41="",'Jogos - Grupos'!G41=""),"-",IF(OR('Apostas - Grupos'!BZ5="",'Apostas - Grupos'!CA5=""),0,IF(AND('Apostas - Grupos'!BZ5='Jogos - Grupos'!F41,'Apostas - Grupos'!CA5='Jogos - Grupos'!G41),5,IF(OR(AND('Jogos - Grupos'!F41='Jogos - Grupos'!G41,'Apostas - Grupos'!BZ5='Apostas - Grupos'!CA5),AND('Jogos - Grupos'!F41>'Jogos - Grupos'!G41,'Apostas - Grupos'!BZ5>'Apostas - Grupos'!CA5),AND('Jogos - Grupos'!F41<'Jogos - Grupos'!G41,'Apostas - Grupos'!BZ5<'Apostas - Grupos'!CA5)),IF(('Apostas - Grupos'!BZ5-'Apostas - Grupos'!CA5)=('Jogos - Grupos'!F41-'Jogos - Grupos'!G41),3,2),0)))) -> - | AO5: =IF(OR('Jogos - Grupos'!F42="",'Jogos - Grupos'!G42=""),"-",IF(OR('Apostas - Grupos'!CB5="",'Apostas - Grupos'!CC5=""),0,IF(AND('Apostas - Grupos'!CB5='Jogos - Grupos'!F42,'Apostas - Grupos'!CC5='Jogos - Grupos'!G42),5,IF(OR(AND('Jogos - Grupos'!F42='Jogos - Grupos'!G42,'Apostas - Grupos'!CB5='Apostas - Grupos'!CC5),AND('Jogos - Grupos'!F42>'Jogos - Grupos'!G42,'Apostas - Grupos'!CB5>'Apostas - Grupos'!CC5),AND('Jogos - Grupos'!F42<'Jogos - Grupos'!G42,'Apostas - Grupos'!CB5<'Apostas - Grupos'!CC5)),IF(('Apostas - Grupos'!CB5-'Apostas - Grupos'!CC5)=('Jogos - Grupos'!F42-'Jogos - Grupos'!G42),3,2),0)))) -> - | AP5: =IF(OR('Jogos - Grupos'!F43="",'Jogos - Grupos'!G43=""),"-",IF(OR('Apostas - Grupos'!CD5="",'Apostas - Grupos'!CE5=""),0,IF(AND('Apostas - Grupos'!CD5='Jogos - Grupos'!F43,'Apostas - Grupos'!CE5='Jogos - Grupos'!G43),5,IF(OR(AND('Jogos - Grupos'!F43='Jogos - Grupos'!G43,'Apostas - Grupos'!CD5='Apostas - Grupos'!CE5),AND('Jogos - Grupos'!F43>'Jogos - Grupos'!G43,'Apostas - Grupos'!CD5>'Apostas - Grupos'!CE5),AND('Jogos - Grupos'!F43<'Jogos - Grupos'!G43,'Apostas - Grupos'!CD5<'Apostas - Grupos'!CE5)),IF(('Apostas - Grupos'!CD5-'Apostas - Grupos'!CE5)=('Jogos - Grupos'!F43-'Jogos - Grupos'!G43),3,2),0)))) -> - | AQ5: =IF(OR('Jogos - Grupos'!F44="",'Jogos - Grupos'!G44=""),"-",IF(OR('Apostas - Grupos'!CF5="",'Apostas - Grupos'!CG5=""),0,IF(AND('Apostas - Grupos'!CF5='Jogos - Grupos'!F44,'Apostas - Grupos'!CG5='Jogos - Grupos'!G44),5,IF(OR(AND('Jogos - Grupos'!F44='Jogos - Grupos'!G44,'Apostas - Grupos'!CF5='Apostas - Grupos'!CG5),AND('Jogos - Grupos'!F44>'Jogos - Grupos'!G44,'Apostas - Grupos'!CF5>'Apostas - Grupos'!CG5),AND('Jogos - Grupos'!F44<'Jogos - Grupos'!G44,'Apostas - Grupos'!CF5<'Apostas - Grupos'!CG5)),IF(('Apostas - Grupos'!CF5-'Apostas - Grupos'!CG5)=('Jogos - Grupos'!F44-'Jogos - Grupos'!G44),3,2),0)))) -> - | AR5: =IF(OR('Jogos - Grupos'!F45="",'Jogos - Grupos'!G45=""),"-",IF(OR('Apostas - Grupos'!CH5="",'Apostas - Grupos'!CI5=""),0,IF(AND('Apostas - Grupos'!CH5='Jogos - Grupos'!F45,'Apostas - Grupos'!CI5='Jogos - Grupos'!G45),5,IF(OR(AND('Jogos - Grupos'!F45='Jogos - Grupos'!G45,'Apostas - Grupos'!CH5='Apostas - Grupos'!CI5),AND('Jogos - Grupos'!F45>'Jogos - Grupos'!G45,'Apostas - Grupos'!CH5>'Apostas - Grupos'!CI5),AND('Jogos - Grupos'!F45<'Jogos - Grupos'!G45,'Apostas - Grupos'!CH5<'Apostas - Grupos'!CI5)),IF(('Apostas - Grupos'!CH5-'Apostas - Grupos'!CI5)=('Jogos - Grupos'!F45-'Jogos - Grupos'!G45),3,2),0)))) -> - | AS5: =IF(OR('Jogos - Grupos'!F46="",'Jogos - Grupos'!G46=""),"-",IF(OR('Apostas - Grupos'!CJ5="",'Apostas - Grupos'!CK5=""),0,IF(AND('Apostas - Grupos'!CJ5='Jogos - Grupos'!F46,'Apostas - Grupos'!CK5='Jogos - Grupos'!G46),5,IF(OR(AND('Jogos - Grupos'!F46='Jogos - Grupos'!G46,'Apostas - Grupos'!CJ5='Apostas - Grupos'!CK5),AND('Jogos - Grupos'!F46>'Jogos - Grupos'!G46,'Apostas - Grupos'!CJ5>'Apostas - Grupos'!CK5),AND('Jogos - Grupos'!F46<'Jogos - Grupos'!G46,'Apostas - Grupos'!CJ5<'Apostas - Grupos'!CK5)),IF(('Apostas - Grupos'!CJ5-'Apostas - Grupos'!CK5)=('Jogos - Grupos'!F46-'Jogos - Grupos'!G46),3,2),0)))) -> - | AT5: =IF(OR('Jogos - Grupos'!F47="",'Jogos - Grupos'!G47=""),"-",IF(OR('Apostas - Grupos'!CL5="",'Apostas - Grupos'!CM5=""),0,IF(AND('Apostas - Grupos'!CL5='Jogos - Grupos'!F47,'Apostas - Grupos'!CM5='Jogos - Grupos'!G47),5,IF(OR(AND('Jogos - Grupos'!F47='Jogos - Grupos'!G47,'Apostas - Grupos'!CL5='Apostas - Grupos'!CM5),AND('Jogos - Grupos'!F47>'Jogos - Grupos'!G47,'Apostas - Grupos'!CL5>'Apostas - Grupos'!CM5),AND('Jogos - Grupos'!F47<'Jogos - Grupos'!G47,'Apostas - Grupos'!CL5<'Apostas - Grupos'!CM5)),IF(('Apostas - Grupos'!CL5-'Apostas - Grupos'!CM5)=('Jogos - Grupos'!F47-'Jogos - Grupos'!G47),3,2),0)))) -> - | AU5: =IF(OR('Jogos - Grupos'!F48="",'Jogos - Grupos'!G48=""),"-",IF(OR('Apostas - Grupos'!CN5="",'Apostas - Grupos'!CO5=""),0,IF(AND('Apostas - Grupos'!CN5='Jogos - Grupos'!F48,'Apostas - Grupos'!CO5='Jogos - Grupos'!G48),5,IF(OR(AND('Jogos - Grupos'!F48='Jogos - Grupos'!G48,'Apostas - Grupos'!CN5='Apostas - Grupos'!CO5),AND('Jogos - Grupos'!F48>'Jogos - Grupos'!G48,'Apostas - Grupos'!CN5>'Apostas - Grupos'!CO5),AND('Jogos - Grupos'!F48<'Jogos - Grupos'!G48,'Apostas - Grupos'!CN5<'Apostas - Grupos'!CO5)),IF(('Apostas - Grupos'!CN5-'Apostas - Grupos'!CO5)=('Jogos - Grupos'!F48-'Jogos - Grupos'!G48),3,2),0)))) -> - | AV5: =IF(OR('Jogos - Grupos'!F49="",'Jogos - Grupos'!G49=""),"-",IF(OR('Apostas - Grupos'!CP5="",'Apostas - Grupos'!CQ5=""),0,IF(AND('Apostas - Grupos'!CP5='Jogos - Grupos'!F49,'Apostas - Grupos'!CQ5='Jogos - Grupos'!G49),5,IF(OR(AND('Jogos - Grupos'!F49='Jogos - Grupos'!G49,'Apostas - Grupos'!CP5='Apostas - Grupos'!CQ5),AND('Jogos - Grupos'!F49>'Jogos - Grupos'!G49,'Apostas - Grupos'!CP5>'Apostas - Grupos'!CQ5),AND('Jogos - Grupos'!F49<'Jogos - Grupos'!G49,'Apostas - Grupos'!CP5<'Apostas - Grupos'!CQ5)),IF(('Apostas - Grupos'!CP5-'Apostas - Grupos'!CQ5)=('Jogos - Grupos'!F49-'Jogos - Grupos'!G49),3,2),0)))) -> - | AW5: =IF(OR('Jogos - Grupos'!F50="",'Jogos - Grupos'!G50=""),"-",IF(OR('Apostas - Grupos'!CR5="",'Apostas - Grupos'!CS5=""),0,IF(AND('Apostas - Grupos'!CR5='Jogos - Grupos'!F50,'Apostas - Grupos'!CS5='Jogos - Grupos'!G50),5,IF(OR(AND('Jogos - Grupos'!F50='Jogos - Grupos'!G50,'Apostas - Grupos'!CR5='Apostas - Grupos'!CS5),AND('Jogos - Grupos'!F50>'Jogos - Grupos'!G50,'Apostas - Grupos'!CR5>'Apostas - Grupos'!CS5),AND('Jogos - Grupos'!F50<'Jogos - Grupos'!G50,'Apostas - Grupos'!CR5<'Apostas - Grupos'!CS5)),IF(('Apostas - Grupos'!CR5-'Apostas - Grupos'!CS5)=('Jogos - Grupos'!F50-'Jogos - Grupos'!G50),3,2),0)))) -> - | AX5: =IF(OR('Jogos - Grupos'!F51="",'Jogos - Grupos'!G51=""),"-",IF(OR('Apostas - Grupos'!CT5="",'Apostas - Grupos'!CU5=""),0,IF(AND('Apostas - Grupos'!CT5='Jogos - Grupos'!F51,'Apostas - Grupos'!CU5='Jogos - Grupos'!G51),5,IF(OR(AND('Jogos - Grupos'!F51='Jogos - Grupos'!G51,'Apostas - Grupos'!CT5='Apostas - Grupos'!CU5),AND('Jogos - Grupos'!F51>'Jogos - Grupos'!G51,'Apostas - Grupos'!CT5>'Apostas - Grupos'!CU5),AND('Jogos - Grupos'!F51<'Jogos - Grupos'!G51,'Apostas - Grupos'!CT5<'Apostas - Grupos'!CU5)),IF(('Apostas - Grupos'!CT5-'Apostas - Grupos'!CU5)=('Jogos - Grupos'!F51-'Jogos - Grupos'!G51),3,2),0)))) -> - | AY5: =IF(OR('Jogos - Grupos'!F52="",'Jogos - Grupos'!G52=""),"-",IF(OR('Apostas - Grupos'!CV5="",'Apostas - Grupos'!CW5=""),0,IF(AND('Apostas - Grupos'!CV5='Jogos - Grupos'!F52,'Apostas - Grupos'!CW5='Jogos - Grupos'!G52),5,IF(OR(AND('Jogos - Grupos'!F52='Jogos - Grupos'!G52,'Apostas - Grupos'!CV5='Apostas - Grupos'!CW5),AND('Jogos - Grupos'!F52>'Jogos - Grupos'!G52,'Apostas - Grupos'!CV5>'Apostas - Grupos'!CW5),AND('Jogos - Grupos'!F52<'Jogos - Grupos'!G52,'Apostas - Grupos'!CV5<'Apostas - Grupos'!CW5)),IF(('Apostas - Grupos'!CV5-'Apostas - Grupos'!CW5)=('Jogos - Grupos'!F52-'Jogos - Grupos'!G52),3,2),0)))) -> - | AZ5: =IF(OR('Jogos - Grupos'!F53="",'Jogos - Grupos'!G53=""),"-",IF(OR('Apostas - Grupos'!CX5="",'Apostas - Grupos'!CY5=""),0,IF(AND('Apostas - Grupos'!CX5='Jogos - Grupos'!F53,'Apostas - Grupos'!CY5='Jogos - Grupos'!G53),5,IF(OR(AND('Jogos - Grupos'!F53='Jogos - Grupos'!G53,'Apostas - Grupos'!CX5='Apostas - Grupos'!CY5),AND('Jogos - Grupos'!F53>'Jogos - Grupos'!G53,'Apostas - Grupos'!CX5>'Apostas - Grupos'!CY5),AND('Jogos - Grupos'!F53<'Jogos - Grupos'!G53,'Apostas - Grupos'!CX5<'Apostas - Grupos'!CY5)),IF(('Apostas - Grupos'!CX5-'Apostas - Grupos'!CY5)=('Jogos - Grupos'!F53-'Jogos - Grupos'!G53),3,2),0)))) -> - | BA5: =IF(OR('Jogos - Grupos'!F54="",'Jogos - Grupos'!G54=""),"-",IF(OR('Apostas - Grupos'!CZ5="",'Apostas - Grupos'!DA5=""),0,IF(AND('Apostas - Grupos'!CZ5='Jogos - Grupos'!F54,'Apostas - Grupos'!DA5='Jogos - Grupos'!G54),5,IF(OR(AND('Jogos - Grupos'!F54='Jogos - Grupos'!G54,'Apostas - Grupos'!CZ5='Apostas - Grupos'!DA5),AND('Jogos - Grupos'!F54>'Jogos - Grupos'!G54,'Apostas - Grupos'!CZ5>'Apostas - Grupos'!DA5),AND('Jogos - Grupos'!F54<'Jogos - Grupos'!G54,'Apostas - Grupos'!CZ5<'Apostas - Grupos'!DA5)),IF(('Apostas - Grupos'!CZ5-'Apostas - Grupos'!DA5)=('Jogos - Grupos'!F54-'Jogos - Grupos'!G54),3,2),0)))) -> - | BB5: =IF(OR('Jogos - Grupos'!F55="",'Jogos - Grupos'!G55=""),"-",IF(OR('Apostas - Grupos'!DB5="",'Apostas - Grupos'!DC5=""),0,IF(AND('Apostas - Grupos'!DB5='Jogos - Grupos'!F55,'Apostas - Grupos'!DC5='Jogos - Grupos'!G55),5,IF(OR(AND('Jogos - Grupos'!F55='Jogos - Grupos'!G55,'Apostas - Grupos'!DB5='Apostas - Grupos'!DC5),AND('Jogos - Grupos'!F55>'Jogos - Grupos'!G55,'Apostas - Grupos'!DB5>'Apostas - Grupos'!DC5),AND('Jogos - Grupos'!F55<'Jogos - Grupos'!G55,'Apostas - Grupos'!DB5<'Apostas - Grupos'!DC5)),IF(('Apostas - Grupos'!DB5-'Apostas - Grupos'!DC5)=('Jogos - Grupos'!F55-'Jogos - Grupos'!G55),3,2),0)))) -> - | BC5: =IF(OR('Jogos - Grupos'!F56="",'Jogos - Grupos'!G56=""),"-",IF(OR('Apostas - Grupos'!DD5="",'Apostas - Grupos'!DE5=""),0,IF(AND('Apostas - Grupos'!DD5='Jogos - Grupos'!F56,'Apostas - Grupos'!DE5='Jogos - Grupos'!G56),5,IF(OR(AND('Jogos - Grupos'!F56='Jogos - Grupos'!G56,'Apostas - Grupos'!DD5='Apostas - Grupos'!DE5),AND('Jogos - Grupos'!F56>'Jogos - Grupos'!G56,'Apostas - Grupos'!DD5>'Apostas - Grupos'!DE5),AND('Jogos - Grupos'!F56<'Jogos - Grupos'!G56,'Apostas - Grupos'!DD5<'Apostas - Grupos'!DE5)),IF(('Apostas - Grupos'!DD5-'Apostas - Grupos'!DE5)=('Jogos - Grupos'!F56-'Jogos - Grupos'!G56),3,2),0)))) -> - | BD5: =IF(OR('Jogos - Grupos'!F57="",'Jogos - Grupos'!G57=""),"-",IF(OR('Apostas - Grupos'!DF5="",'Apostas - Grupos'!DG5=""),0,IF(AND('Apostas - Grupos'!DF5='Jogos - Grupos'!F57,'Apostas - Grupos'!DG5='Jogos - Grupos'!G57),5,IF(OR(AND('Jogos - Grupos'!F57='Jogos - Grupos'!G57,'Apostas - Grupos'!DF5='Apostas - Grupos'!DG5),AND('Jogos - Grupos'!F57>'Jogos - Grupos'!G57,'Apostas - Grupos'!DF5>'Apostas - Grupos'!DG5),AND('Jogos - Grupos'!F57<'Jogos - Grupos'!G57,'Apostas - Grupos'!DF5<'Apostas - Grupos'!DG5)),IF(('Apostas - Grupos'!DF5-'Apostas - Grupos'!DG5)=('Jogos - Grupos'!F57-'Jogos - Grupos'!G57),3,2),0)))) -> - | BE5: =IF(OR('Jogos - Grupos'!F58="",'Jogos - Grupos'!G58=""),"-",IF(OR('Apostas - Grupos'!DH5="",'Apostas - Grupos'!DI5=""),0,IF(AND('Apostas - Grupos'!DH5='Jogos - Grupos'!F58,'Apostas - Grupos'!DI5='Jogos - Grupos'!G58),5,IF(OR(AND('Jogos - Grupos'!F58='Jogos - Grupos'!G58,'Apostas - Grupos'!DH5='Apostas - Grupos'!DI5),AND('Jogos - Grupos'!F58>'Jogos - Grupos'!G58,'Apostas - Grupos'!DH5>'Apostas - Grupos'!DI5),AND('Jogos - Grupos'!F58<'Jogos - Grupos'!G58,'Apostas - Grupos'!DH5<'Apostas - Grupos'!DI5)),IF(('Apostas - Grupos'!DH5-'Apostas - Grupos'!DI5)=('Jogos - Grupos'!F58-'Jogos - Grupos'!G58),3,2),0)))) -> - | BF5: =IF(OR('Jogos - Grupos'!F59="",'Jogos - Grupos'!G59=""),"-",IF(OR('Apostas - Grupos'!DJ5="",'Apostas - Grupos'!DK5=""),0,IF(AND('Apostas - Grupos'!DJ5='Jogos - Grupos'!F59,'Apostas - Grupos'!DK5='Jogos - Grupos'!G59),5,IF(OR(AND('Jogos - Grupos'!F59='Jogos - Grupos'!G59,'Apostas - Grupos'!DJ5='Apostas - Grupos'!DK5),AND('Jogos - Grupos'!F59>'Jogos - Grupos'!G59,'Apostas - Grupos'!DJ5>'Apostas - Grupos'!DK5),AND('Jogos - Grupos'!F59<'Jogos - Grupos'!G59,'Apostas - Grupos'!DJ5<'Apostas - Grupos'!DK5)),IF(('Apostas - Grupos'!DJ5-'Apostas - Grupos'!DK5)=('Jogos - Grupos'!F59-'Jogos - Grupos'!G59),3,2),0)))) -> - | BG5: =IF(OR('Jogos - Grupos'!F60="",'Jogos - Grupos'!G60=""),"-",IF(OR('Apostas - Grupos'!DL5="",'Apostas - Grupos'!DM5=""),0,IF(AND('Apostas - Grupos'!DL5='Jogos - Grupos'!F60,'Apostas - Grupos'!DM5='Jogos - Grupos'!G60),5,IF(OR(AND('Jogos - Grupos'!F60='Jogos - Grupos'!G60,'Apostas - Grupos'!DL5='Apostas - Grupos'!DM5),AND('Jogos - Grupos'!F60>'Jogos - Grupos'!G60,'Apostas - Grupos'!DL5>'Apostas - Grupos'!DM5),AND('Jogos - Grupos'!F60<'Jogos - Grupos'!G60,'Apostas - Grupos'!DL5<'Apostas - Grupos'!DM5)),IF(('Apostas - Grupos'!DL5-'Apostas - Grupos'!DM5)=('Jogos - Grupos'!F60-'Jogos - Grupos'!G60),3,2),0)))) -> - | BH5: =IF(OR('Jogos - Grupos'!F61="",'Jogos - Grupos'!G61=""),"-",IF(OR('Apostas - Grupos'!DN5="",'Apostas - Grupos'!DO5=""),0,IF(AND('Apostas - Grupos'!DN5='Jogos - Grupos'!F61,'Apostas - Grupos'!DO5='Jogos - Grupos'!G61),5,IF(OR(AND('Jogos - Grupos'!F61='Jogos - Grupos'!G61,'Apostas - Grupos'!DN5='Apostas - Grupos'!DO5),AND('Jogos - Grupos'!F61>'Jogos - Grupos'!G61,'Apostas - Grupos'!DN5>'Apostas - Grupos'!DO5),AND('Jogos - Grupos'!F61<'Jogos - Grupos'!G61,'Apostas - Grupos'!DN5<'Apostas - Grupos'!DO5)),IF(('Apostas - Grupos'!DN5-'Apostas - Grupos'!DO5)=('Jogos - Grupos'!F61-'Jogos - Grupos'!G61),3,2),0)))) -> - | BI5: =IF(OR('Jogos - Grupos'!F62="",'Jogos - Grupos'!G62=""),"-",IF(OR('Apostas - Grupos'!DP5="",'Apostas - Grupos'!DQ5=""),0,IF(AND('Apostas - Grupos'!DP5='Jogos - Grupos'!F62,'Apostas - Grupos'!DQ5='Jogos - Grupos'!G62),5,IF(OR(AND('Jogos - Grupos'!F62='Jogos - Grupos'!G62,'Apostas - Grupos'!DP5='Apostas - Grupos'!DQ5),AND('Jogos - Grupos'!F62>'Jogos - Grupos'!G62,'Apostas - Grupos'!DP5>'Apostas - Grupos'!DQ5),AND('Jogos - Grupos'!F62<'Jogos - Grupos'!G62,'Apostas - Grupos'!DP5<'Apostas - Grupos'!DQ5)),IF(('Apostas - Grupos'!DP5-'Apostas - Grupos'!DQ5)=('Jogos - Grupos'!F62-'Jogos - Grupos'!G62),3,2),0)))) -> - | BJ5: =IF(OR('Jogos - Grupos'!F63="",'Jogos - Grupos'!G63=""),"-",IF(OR('Apostas - Grupos'!DR5="",'Apostas - Grupos'!DS5=""),0,IF(AND('Apostas - Grupos'!DR5='Jogos - Grupos'!F63,'Apostas - Grupos'!DS5='Jogos - Grupos'!G63),5,IF(OR(AND('Jogos - Grupos'!F63='Jogos - Grupos'!G63,'Apostas - Grupos'!DR5='Apostas - Grupos'!DS5),AND('Jogos - Grupos'!F63>'Jogos - Grupos'!G63,'Apostas - Grupos'!DR5>'Apostas - Grupos'!DS5),AND('Jogos - Grupos'!F63<'Jogos - Grupos'!G63,'Apostas - Grupos'!DR5<'Apostas - Grupos'!DS5)),IF(('Apostas - Grupos'!DR5-'Apostas - Grupos'!DS5)=('Jogos - Grupos'!F63-'Jogos - Grupos'!G63),3,2),0)))) -> - | BK5: =IF(OR('Jogos - Grupos'!F64="",'Jogos - Grupos'!G64=""),"-",IF(OR('Apostas - Grupos'!DT5="",'Apostas - Grupos'!DU5=""),0,IF(AND('Apostas - Grupos'!DT5='Jogos - Grupos'!F64,'Apostas - Grupos'!DU5='Jogos - Grupos'!G64),5,IF(OR(AND('Jogos - Grupos'!F64='Jogos - Grupos'!G64,'Apostas - Grupos'!DT5='Apostas - Grupos'!DU5),AND('Jogos - Grupos'!F64>'Jogos - Grupos'!G64,'Apostas - Grupos'!DT5>'Apostas - Grupos'!DU5),AND('Jogos - Grupos'!F64<'Jogos - Grupos'!G64,'Apostas - Grupos'!DT5<'Apostas - Grupos'!DU5)),IF(('Apostas - Grupos'!DT5-'Apostas - Grupos'!DU5)=('Jogos - Grupos'!F64-'Jogos - Grupos'!G64),3,2),0)))) -> - | BL5: =IF(OR('Jogos - Grupos'!F65="",'Jogos - Grupos'!G65=""),"-",IF(OR('Apostas - Grupos'!DV5="",'Apostas - Grupos'!DW5=""),0,IF(AND('Apostas - Grupos'!DV5='Jogos - Grupos'!F65,'Apostas - Grupos'!DW5='Jogos - Grupos'!G65),5,IF(OR(AND('Jogos - Grupos'!F65='Jogos - Grupos'!G65,'Apostas - Grupos'!DV5='Apostas - Grupos'!DW5),AND('Jogos - Grupos'!F65>'Jogos - Grupos'!G65,'Apostas - Grupos'!DV5>'Apostas - Grupos'!DW5),AND('Jogos - Grupos'!F65<'Jogos - Grupos'!G65,'Apostas - Grupos'!DV5<'Apostas - Grupos'!DW5)),IF(('Apostas - Grupos'!DV5-'Apostas - Grupos'!DW5)=('Jogos - Grupos'!F65-'Jogos - Grupos'!G65),3,2),0)))) -> - | BM5: =IF(OR('Jogos - Grupos'!F66="",'Jogos - Grupos'!G66=""),"-",IF(OR('Apostas - Grupos'!DX5="",'Apostas - Grupos'!DY5=""),0,IF(AND('Apostas - Grupos'!DX5='Jogos - Grupos'!F66,'Apostas - Grupos'!DY5='Jogos - Grupos'!G66),5,IF(OR(AND('Jogos - Grupos'!F66='Jogos - Grupos'!G66,'Apostas - Grupos'!DX5='Apostas - Grupos'!DY5),AND('Jogos - Grupos'!F66>'Jogos - Grupos'!G66,'Apostas - Grupos'!DX5>'Apostas - Grupos'!DY5),AND('Jogos - Grupos'!F66<'Jogos - Grupos'!G66,'Apostas - Grupos'!DX5<'Apostas - Grupos'!DY5)),IF(('Apostas - Grupos'!DX5-'Apostas - Grupos'!DY5)=('Jogos - Grupos'!F66-'Jogos - Grupos'!G66),3,2),0)))) -> - | BN5: =IF(OR('Jogos - Grupos'!F67="",'Jogos - Grupos'!G67=""),"-",IF(OR('Apostas - Grupos'!DZ5="",'Apostas - Grupos'!EA5=""),0,IF(AND('Apostas - Grupos'!DZ5='Jogos - Grupos'!F67,'Apostas - Grupos'!EA5='Jogos - Grupos'!G67),5,IF(OR(AND('Jogos - Grupos'!F67='Jogos - Grupos'!G67,'Apostas - Grupos'!DZ5='Apostas - Grupos'!EA5),AND('Jogos - Grupos'!F67>'Jogos - Grupos'!G67,'Apostas - Grupos'!DZ5>'Apostas - Grupos'!EA5),AND('Jogos - Grupos'!F67<'Jogos - Grupos'!G67,'Apostas - Grupos'!DZ5<'Apostas - Grupos'!EA5)),IF(('Apostas - Grupos'!DZ5-'Apostas - Grupos'!EA5)=('Jogos - Grupos'!F67-'Jogos - Grupos'!G67),3,2),0)))) -> - | BO5: =IF(OR('Jogos - Grupos'!F68="",'Jogos - Grupos'!G68=""),"-",IF(OR('Apostas - Grupos'!EB5="",'Apostas - Grupos'!EC5=""),0,IF(AND('Apostas - Grupos'!EB5='Jogos - Grupos'!F68,'Apostas - Grupos'!EC5='Jogos - Grupos'!G68),5,IF(OR(AND('Jogos - Grupos'!F68='Jogos - Grupos'!G68,'Apostas - Grupos'!EB5='Apostas - Grupos'!EC5),AND('Jogos - Grupos'!F68>'Jogos - Grupos'!G68,'Apostas - Grupos'!EB5>'Apostas - Grupos'!EC5),AND('Jogos - Grupos'!F68<'Jogos - Grupos'!G68,'Apostas - Grupos'!EB5<'Apostas - Grupos'!EC5)),IF(('Apostas - Grupos'!EB5-'Apostas - Grupos'!EC5)=('Jogos - Grupos'!F68-'Jogos - Grupos'!G68),3,2),0)))) -> - | BP5: =IF(OR('Jogos - Grupos'!F69="",'Jogos - Grupos'!G69=""),"-",IF(OR('Apostas - Grupos'!ED5="",'Apostas - Grupos'!EE5=""),0,IF(AND('Apostas - Grupos'!ED5='Jogos - Grupos'!F69,'Apostas - Grupos'!EE5='Jogos - Grupos'!G69),5,IF(OR(AND('Jogos - Grupos'!F69='Jogos - Grupos'!G69,'Apostas - Grupos'!ED5='Apostas - Grupos'!EE5),AND('Jogos - Grupos'!F69>'Jogos - Grupos'!G69,'Apostas - Grupos'!ED5>'Apostas - Grupos'!EE5),AND('Jogos - Grupos'!F69<'Jogos - Grupos'!G69,'Apostas - Grupos'!ED5<'Apostas - Grupos'!EE5)),IF(('Apostas - Grupos'!ED5-'Apostas - Grupos'!EE5)=('Jogos - Grupos'!F69-'Jogos - Grupos'!G69),3,2),0)))) -> - | BQ5: =IF(OR('Jogos - Grupos'!F70="",'Jogos - Grupos'!G70=""),"-",IF(OR('Apostas - Grupos'!EF5="",'Apostas - Grupos'!EG5=""),0,IF(AND('Apostas - Grupos'!EF5='Jogos - Grupos'!F70,'Apostas - Grupos'!EG5='Jogos - Grupos'!G70),5,IF(OR(AND('Jogos - Grupos'!F70='Jogos - Grupos'!G70,'Apostas - Grupos'!EF5='Apostas - Grupos'!EG5),AND('Jogos - Grupos'!F70>'Jogos - Grupos'!G70,'Apostas - Grupos'!EF5>'Apostas - Grupos'!EG5),AND('Jogos - Grupos'!F70<'Jogos - Grupos'!G70,'Apostas - Grupos'!EF5<'Apostas - Grupos'!EG5)),IF(('Apostas - Grupos'!EF5-'Apostas - Grupos'!EG5)=('Jogos - Grupos'!F70-'Jogos - Grupos'!G70),3,2),0)))) -> - | BR5: =IF(OR('Jogos - Grupos'!F71="",'Jogos - Grupos'!G71=""),"-",IF(OR('Apostas - Grupos'!EH5="",'Apostas - Grupos'!EI5=""),0,IF(AND('Apostas - Grupos'!EH5='Jogos - Grupos'!F71,'Apostas - Grupos'!EI5='Jogos - Grupos'!G71),5,IF(OR(AND('Jogos - Grupos'!F71='Jogos - Grupos'!G71,'Apostas - Grupos'!EH5='Apostas - Grupos'!EI5),AND('Jogos - Grupos'!F71>'Jogos - Grupos'!G71,'Apostas - Grupos'!EH5>'Apostas - Grupos'!EI5),AND('Jogos - Grupos'!F71<'Jogos - Grupos'!G71,'Apostas - Grupos'!EH5<'Apostas - Grupos'!EI5)),IF(('Apostas - Grupos'!EH5-'Apostas - Grupos'!EI5)=('Jogos - Grupos'!F71-'Jogos - Grupos'!G71),3,2),0)))) -> - | BS5: =IF(OR('Jogos - Grupos'!F72="",'Jogos - Grupos'!G72=""),"-",IF(OR('Apostas - Grupos'!EJ5="",'Apostas - Grupos'!EK5=""),0,IF(AND('Apostas - Grupos'!EJ5='Jogos - Grupos'!F72,'Apostas - Grupos'!EK5='Jogos - Grupos'!G72),5,IF(OR(AND('Jogos - Grupos'!F72='Jogos - Grupos'!G72,'Apostas - Grupos'!EJ5='Apostas - Grupos'!EK5),AND('Jogos - Grupos'!F72>'Jogos - Grupos'!G72,'Apostas - Grupos'!EJ5>'Apostas - Grupos'!EK5),AND('Jogos - Grupos'!F72<'Jogos - Grupos'!G72,'Apostas - Grupos'!EJ5<'Apostas - Grupos'!EK5)),IF(('Apostas - Grupos'!EJ5-'Apostas - Grupos'!EK5)=('Jogos - Grupos'!F72-'Jogos - Grupos'!G72),3,2),0)))) -> - | BT5: =IF(OR('Jogos - Grupos'!F73="",'Jogos - Grupos'!G73=""),"-",IF(OR('Apostas - Grupos'!EL5="",'Apostas - Grupos'!EM5=""),0,IF(AND('Apostas - Grupos'!EL5='Jogos - Grupos'!F73,'Apostas - Grupos'!EM5='Jogos - Grupos'!G73),5,IF(OR(AND('Jogos - Grupos'!F73='Jogos - Grupos'!G73,'Apostas - Grupos'!EL5='Apostas - Grupos'!EM5),AND('Jogos - Grupos'!F73>'Jogos - Grupos'!G73,'Apostas - Grupos'!EL5>'Apostas - Grupos'!EM5),AND('Jogos - Grupos'!F73<'Jogos - Grupos'!G73,'Apostas - Grupos'!EL5<'Apostas - Grupos'!EM5)),IF(('Apostas - Grupos'!EL5-'Apostas - Grupos'!EM5)=('Jogos - Grupos'!F73-'Jogos - Grupos'!G73),3,2),0)))) -> - | BU5: =IF(OR('Jogos - Grupos'!F74="",'Jogos - Grupos'!G74=""),"-",IF(OR('Apostas - Grupos'!EN5="",'Apostas - Grupos'!EO5=""),0,IF(AND('Apostas - Grupos'!EN5='Jogos - Grupos'!F74,'Apostas - Grupos'!EO5='Jogos - Grupos'!G74),5,IF(OR(AND('Jogos - Grupos'!F74='Jogos - Grupos'!G74,'Apostas - Grupos'!EN5='Apostas - Grupos'!EO5),AND('Jogos - Grupos'!F74>'Jogos - Grupos'!G74,'Apostas - Grupos'!EN5>'Apostas - Grupos'!EO5),AND('Jogos - Grupos'!F74<'Jogos - Grupos'!G74,'Apostas - Grupos'!EN5<'Apostas - Grupos'!EO5)),IF(('Apostas - Grupos'!EN5-'Apostas - Grupos'!EO5)=('Jogos - Grupos'!F74-'Jogos - Grupos'!G74),3,2),0)))) -> - | BV5: =SUM(B5:BU5) -> 0
